Workbook
Name 보호된행_삭제필요: '10.통화'!$82:$82

Sheet 변경사항
B2: 1. 템플릿 변경 이력
B3: 버전 | C3: 일자 | D3: 내용 | E3: 비고
B4: v2.0.1 | C4: 2024.07.02 | D4: 1. 참조 오류 수정 ㄴ 결과 시트 시트명 참조 오류 수정 ㄴ TC 시트 하단 통계 참조 오류 수정
B5: v2.0 | C5: 2024.06.20 | D5: 1. '결과' 시트 통계 개선 - 플랫폼 그룹별로 전체 통계 필터 가능 - 시트명 그룹별 전체 통계 필터 가능 (시트명x이터레이션x환경 조합) - 2개 이상 시트를 (결과 시트내)시트명을 통일하여 통계 가능 2. 테스트케이스 시트 (하단) 통계 개선 - Prority 통계 추가 및 필터 추가 (연산자 사용하여 필터링 범위 지정 가능) - 이터레이션, 플랫폼 그룹 필터링 가능 4. 입력값 제한 추가 - 표준화된 입력값을 사용해야 되는 경우, '입력값' 시트 기준으로 입력 제한 5. 통계 영역 셀 잠금 추가 - 실수 방지를 위해서 통계 영역 위주로 잠금 추가 (알럿 후, 수정이 가능하므로 주의 필요) 6. 테스트케이스 결과 입력 필드 조건부 서식 컬러 변경 7. '2023년 X차' (미사용) 시트 제거
B6: v1.3 | C6: 2023.09.15 | D6: 1. 스프린트 일정 및 과제 대시보드 목적의 시트 통합 및 시트 숨김 처리 2. 테스트 수행 결과, 분류 항목 업데이트 | E6: 1. 23년 8차부터 해당 시트 사용하지 않는 방향
B7: v1.2.1 | C7: 2021.12.20 | D7: 1. 테스트 영향 범위 (수행 대상 플랫폼) field에 항목 추가 - moWeb, pcWeb, Web, Wear, Watch | E7: 항목추가 결정
B8: v1.2 | C8: 2021.11.23 | D8: 1. 우측 필드 개편 - as-is : [Comment] [Jira] / [TC Review] [Spec Review] - to-be : [Comment & Jira] [Spec Review] [TC Review] 2. 테스트 영향 범위 (수행 대상 플랫폼) field에 "web" 및 "wear"추가 - 30번 시트에 "Moweb", "PCWeb", "Wear"를 추가 3. OS coverage 변경 - as-is : a4~a10, i11~i13 - to-be : a6~a12, i13~i15
B9: v1.1 | C9: 2019.05.13 | D9: 1. 테스트 케이스 시트 하단, 'b' 통계 행 참조 오류 수정 - 모든 테스트 케이스 시트에서 I 열부터 b 통계 참조를 x3:x298 > x5:x300
B10: v1.0 | C10: 2019.05.08 | D10: 1. 불필요한 시트 제거 2. v1.0 릴리즈
B11: v0.6 | C11: 2019.05.07 | D11: 1. Iteration 필드 필수 항목으로 추가 - Iter + env 조합(유니크)으로 결과 시트 전체 통계 취합됨 2. 테스트 케이스 시트 50개 사용가능하도록 적용 - 신규 생성하거나 시트를 복제하는 경우, 통계시트에 취합되지 않음 3. 필드별 메모 추가 - 메모에 간단한 설명 추가
B13: 2. 템플릿 개선 예정 항목 (작업이 완료되면 변경 이력에 남기고 삭제)
B14: No. | C14: 요청 | D14: 내용 | E14: 비고
B15: 1 | C15: linu | D15: 데이터 확인 규칙 필드에 대한 입력값 관리를 모든 시트 공통 관리 할수 있게 개선 ㄴ 별도 시트에 테이블 만들어 참조 할수 있게 | E15: v2.0에 반영
B16: 2 | C16: yama | D16: 결과시트의 구조 개선 : 결과 시트에 세로방향에 입력되는 정보가 참조하는 곳이 각 시트의 하단 현황 셀들(가로방향)이라 결과 시트 편집시 스프레드로 자연스럽고 빠른 편집이 불가 - 결과 구조를 세로방향으로 해야 하는 것은 변경이 어려울듯 - 결과 시트의 결과값 데이터 종횡 구성을 각시트의 구성 방향과 동일하게 가져가면 시트 추가/삭제 등으로 결과시트를 편집해야 할 때 편리할 것으로 예상 | E16: (6/20) 테스트 케이스 구조 및 시각 흐름에 따라 현상태 유지
B17: 3
B18: 4
B19: 5
B20: 6
B21: 7
B22: 8
B23: 9
B24: 10

Sheet 입력값
B1: OS / Browser | F1: Iteration | I1: Category | L1: Priority | O1: Result | R1: 범위 | U1: 안내 문구
B2: 표시 | C2: 구분 (그룹) | D2: 설명 | F2: 표시 | G2: 설명 | I2: 표시 | J2: 설명 | L2: 표시 | M2: 설명 | O2: 표시 | P2: 설명 | R2: 표시 | S2: 설명 | U2: 위치 | V2: 문구
B3: a10 | C3: Android | D3: Android 10 | F3: 1 | I3: app | J3: iOS + Android | L3: 1 | M3: 숫자가 낮을 수록 우선순위 높음 | O3: p | P3: pass | R3: = | U3: A1 (첫행) | V3: 테스트 케이스 작성자를 입력해주세요. 리뷰어가 있으면 함께 입력해주세요. (참조 수식을 삭제하고 입력하세요) - 예시) 작성 : kakao.talk (리뷰 : qa.talk)
B4: a11 | C4: Android | D4: Android 11 | F4: 2 | I4: I | J4: iOS | L4: 2 | O4: f | P4: fail | R4: <= | U4: A300 (마지막행) | V4: 행 추가시 이 라인 위 영역을 선택하고 행을 추가 하셔야 통계 및 서식이 올바르게 적용됩니다.
B5: a12 | C5: Android | D5: Android 12 | F5: 3 | I5: A | J5: Android | L5: 3 | O5: b | P5: block | R5: >=
B6: a13 | C6: Android | D6: Android 13 | F6: 4 | I6: pc | J6: Windows + macOS | L6: 4 | O6: n | P6: not include
B7: a14 | C7: Android | D7: Android 14 | F7: 5 | I7: Win | J7: Windows | L7: 5 | O7: / | P7: 해당 없음
B8: a15 | C8: Android | D8: Android 15 | F8: 6 | I8: Mac | J8: macOS | L8: - | M8: 수행할 TC가 아닌 경우 (테스트 커버리지 제외) | O8: - | P8: TC 아님
B9: a16 | C9: Android | D9: Android 16 | F9: 7 | I9: Web | J9: mobile Web + pc Web
B10: i17 | C10: iOS | D10: iOS 17 | F10: 8 | I10: moWeb | J10: mobile Web
B11: i18 | C11: iOS | D11: iOS 18 | F11: 9 | I11: pcWeb | J11: pc (데스크탑) Web
B12: i26 | C12: iOS | D12: iOS 26 | F12: 10 | I12: ww | J12: Wear OS + WatchOS
B13: w10 | C13: Windows | D13: Windows 10 | F13: 11 | I13: Wear | J13: Google Wear OS
B14: w11 | C14: Windows | D14: Windows 11 | F14: 12 | I14: Watch | J14: Apple WatchOS
B15: m10.15.x | C15: macOS | D15: macOS 10.15.x | I15: - | J15: 수행결과 표기 대상 아님
B16: m11.x | C16: macOS | D16: macOS 11.x
B17: m12.x | C17: macOS | D17: macOS 12.x
B18: m13.x | C18: macOS | D18: macOS 13.x
B19: m14.x | C19: macOS | D19: macOS 14.x
B20: at10 | C20: Android Tablet | D20: Tablet Android 10
B21: at11 | C21: Android Tablet | D21: Tablet Android 11
B22: at12 | C22: Android Tablet | D22: Tablet Android 12
B23: at13 | C23: Android Tablet | D23: Tablet Android 13
B24: at14 | C24: Android Tablet | D24: Tablet Android 14
B25: at15 | C25: Android Tablet | D25: Tablet Android 15
B26: at16 | C26: Android Tablet | D26: Tablet Android 16
B27: it17 | C27: iPad | D27: iPad OS 17
... B46: a_dm | C46: Mobile Web | D46: Daum App

Sheet 리그레션 플랜
B2: 리그레션 테스트 일정 | J2: QA 릴리즈 당번
B3: - 노모어커밋 : 2026.07.07(화) | J3: - Android : @joy.2
B4: - 서브밋 : 2026.07.13(월) | J4: - iOS : @yama.moto
B5: ㄴ 업데이트 테스트: 오전 10시 예정
B6: ㄴ 빌드 공유: 오후 12시 이후 예정 | J6: 이슈 어사인 담당자
J7: - 담당자 없는 이슈 : 릴리즈 당번
B8: 리그레션 테스트 | J8: - 세부 기능/서비스 담당자 있는 경우 : 해당 담당자 (WIKI)
B9: 1. (통합 상세) 리그레션 테스트
B10: - 진행 방식 : 매 차수 OS 분배가 지정됨. (WIKI)
B11: 수행 쉬트 | C11: ZESQ | D11: INNOI + ONYCOM
B12: 1~16 | C12: a16 | D12: i18
B13: 17~27 | C13: i26 | D13: a15
B14: @당번 이 표에 입력한 값은 각 탭의 수행할 OS로 자동 입력됩니다.
B15: ◁ 연간 OS 분배 계획표 펼치기
B16: 수행 쉬트 | C16: 2026/7 (Z) + (I+O) | D16: 2026/8 (Z) + (I+O) | E16: 2026/10 (Z) + (I+O) | F16: 2026/11 (Z) + (I+O) | G16: 2027/1 (Z) + (I+O) | H16: 2027/1 (Z) + (I+O) | I16: 2027/2 (Z) + (I+O) | J16: 2027/3 (Z) + (I+O) | K16: 2027/4 (Z) + (I+O)
B17: 1~16 | C17: i26 / a16 | D17: a15 / i26 | E17: a16 / i18 | F17: i26 / a16 | G17: a15 / i26 | H17: a15 / i26 | I17: i18 / a15 | J17: a16 / i18 | K17: i26 / a16
B18: 17~26 | C18: a15 / i18 | D18: i18 / a16 | E18: i26 / a15 | F18: a15 / i18 | G18: i18 / a16 | H18: i18 / a16 | I18: a16 / i26 | J18: i26 / a15 | K18: a15 / i18
B19: 이 표는 항상 접어 둡니다. ①14~15행에 분배할 OS를 기입한 후, ②혼동 방지를 위해 18~20행에 기입된 내용울 지워 주세요. 회사명만 바꿔서 기입하면 안됩니다. 이 표에서 "수행쉬트 1~16"이 "i18 / a15"라면, 위 표의 "수행쉬트 1~16"에 순서대로 각각 i18, a15를 기입해 주세요. *회사 항목은 항상 고정입니다.
B21: 2. (핵심) 리그레션 테스트 : 3. 2026년 6차 (핵심) KakaoTalk Regression TestCase
B22: - 진행 방식 : OS 및 진행 담당 회사 고정. 매년 1차에 진행 담당 회사 변경.
B23: 수행 쉬트 | C23: ZESQ | D23: INNOI + ONYCOM
B24: 1~2 | C24: a10, a12, i17 | D24: a11, a13, a14
B25: 3~4 | C25: a11, a13, a14 | D25: a10, a12, i17
B26: 5 | C26: a14, i17 = Global a15 = US | D26: a13, i26 = Japan i18 = US
B27: 6 | C27: 업데이트 테스트 담당 OS에서 수행 (6차 미진행)
B29: 업데이트 테스트 / 패치
B30: 1. 담당 플랫폼
B31: OS | C31: 수행 (매 차수 변경) | E31: 리딩담당 (매 차수 변경) 2개사 협업 시 이번 차수 리딩업체 기재 | G31: 빌드 링크
B32: Android | C32: ZESQ | E32: ZESQ
B33: iOS | C33: ONYCOM + INNOI | E33: INNOI
B34: Wear OS | C34: ssoya그룹 | E34: ssoya 그룹 | G34: -
B35: watchOS | C35: ssoya그룹 | E35: ssoya 그룹 | G35: -
B37: 2. 업데이트 테스트 완료 공유
B38: - 1개사 단독으로 진행되는 경우, 해당 사에서 업데이트 테스트 완료 여부를 취합하여 공유
B39: - 2개사 협업으로 진행되는 경우, 로테이션 순번인 리딩담당 업체가 테스트 완료 여부를 취합하여 공유
B40: ㄴONYCOM ▷ INNOI 순으로 로테이션 진행 (2026년 6차 = INNOI)
B43: 수행 시간 모니터링 | D43: *문의: yama
B44: Regression TC 수행 시간 모니터링
B45: ㄴ 위 문서에서 수행할 차수에 맞는 탭에 매 차수 기록
B48: 리그레션 제외 영역
...

Sheet 리그레션 확인 목록
A1: Jira의 "Regression" label이 붙은 이슈를 확인하고 결과를 입력하기 위한 시트 | C1: OS 커버리지 설정 방법 - 기본 테스트 범위는 모든 OS입니다. - 리스트업 하는 본인의 판단 하에 테스트할 OS 범위를 조정해 주세요. (수행하지 않는 OS version에 n처리)
A2: Jira Link | B2: Summary (테스트할 범위 등) | C2: a10 | D2: a11 | E2: a12 | F2: a13 | G2: a14 | H2: a15 | I2: a16 | J2: i17 | K2: i18 | L2: i26 | M2: Comment | N2: Spec & Tip | O2: TC Review | P2: closed?
A3: PLATF-6453 | B3: [Android] Kotlin 2.2.21 적용 - 마이너버전 업데이트 - 리그레션 시 크래시, ANR, 전체 기능 확인 후 이슈 없으면 클로즈 | J3: n | K3: n | L3: n | M3: @zesq (엘리) ㄴA10~14 핵심 TC 결과 참고 ㄴA15~16 통합 상세 TC 결과 참고
A4: PLATF-6417 | B4: (yama가 진행) Liquid Glass UI 오픈 채팅방쪽은 패드쪽(스플릿뷰) 추가 이슈가 많이 보인다고, QA에 지원 요청이 있었습니다. 적용 완료 여부 및 주요 점검 포인트에 대한 정보가 공유되면 해당 부분 참고해서 리글 전에 지원할수 있는 부분은 지원을 검토 부탁드립니다. 각 과제별 담당자에게도 전파하여 과제 진행 및 리글 진행시 폰/패드(스플릿뷰)에서 점검이 되도록 공유가 필요할것 같습니다. >> iPad의 스플릿뷰에 한해서 채팅방스쿼드 및 플랫폼개발에서 공유해 준 화면 우선순위 목록을 참고하여 탐색적 테스트 진행 | C4: n | D4: n | E4: n | F4: n | G4: n | H4: n | I4: n | J4: p | K4: p | L4: p | M4: (yama, 7/3) yama 그룹에서 테스트 진행중입니다. 테스트 완료되면 p처리 후 완료 예정입니다 >> 아이패드 리퀴드 글라스 디자인 적용 이슈 리스트 >> 완료 | P4: p
A5: PLATF-6199 | B5: (담당자 : moz) - iOS/Android 미디어 말풍선 전송 API가 변경되었습니다. 점진 배포 예정으로, 특정 채팅방에는 적용되도록 설정하여 리그레션시 확인이 필요합니다. 일반채팅탭, 수행하시는 TE분 연락주시면 chatid등록 후 테스트 진행되도록 요청할 예정입니다. 일반채팅, 팀채팅 테스트 진행하시는 TE분 지정되시면 연락해주시면 확인 후 등록 요청하여 테스트 진행필요합니다. | C5: - | D5: - | E5: - | F5: - | G5: - | H5: - | I5: - | J5: 진 | K5: 코코 | L5: 미아 | M5: innoi & zesq 동시 진행 모즈에게 문의 후 처리 A10~14, i17.0: 진행 여부 확인 후 지정 chatid 일괄적으로 취합 후 요청 예정_@엘리 I18: innoi 진행 A16: Zesq 진행
A6: PLATF-6367 | B6: API 단위로 테스트는 필요하지 않고, 메시징 연결 관련 주요 동작 확인 [테스트 범위] : 메시징 연결 관련 기본 동작 위주 확인 - 톡 실행 후 정상 동작 여부 (재접속 케이스 고려) - 메시지 수/발신 동작 여부 >> 리그레션 테스트로 대응 >> 6차 브랜치에 머지된 상태로 과제 테스트가 진행되므로, 해당 변경 사항의 영향으로 메시징 서버와 연결에 문제가 있다면, 메시징 관련 일반적인 기능이 동작하지 않을 것이므로, 기본 동작에 대한 점검이 될 것으로 예상 * 메시징 서버: CBT까지 배포된 상태 ㄴ 리얼 배포 : 7/8 예정 | C6: 리지 | D6: 아몬 (대여) | E6: 아도라 | F6: 미아 | G6: 제이니 | H6: 유미 | I6: 소비 | J6: n | K6: n | L6: n | M6: @zesq (메시지 그룹 진행)
A7: EMOTICON-9571 | B7: (담당자 : moz) - iOS * revision 관리코드 변경 이모티콘 구매, 선물, 다운로드 -> 키보드에 바로 꽂힘 서브디바이스에서 키보드 순서 변경 -> 키보드에서 순서 변경 반영 - 이모티콘 리그레션 TC내 관련 내용 포함되어있습니다. 이슈있는 경우 추가 확인을 위해 담당자 연락해주세요. | C7: n | D7: n | E7: n | F7: n | G7: n | H7: n | I7: n | M7: onycom
A8: EMOTICON-9524 | B8: (담당자 : moz) - iOS 스토어 테마 클라이언트 코드 제거 - 설정 내 기본, 커스텀 테마 다운/적용 기능 확인 시 이슈있는 경우 별도 연락 부탁드려요. | C8: n | D8: n | E8: n | F8: n | G8: n | H8: n | I8: n | J8: 진 | K8: 코코 | L8: 미아 | M8: innoi
A9: ATEAM-27892 | B9: 공유 피커에 대한 리그레션 테스트 진행 후 이슈 없으면 클로즈 | J9: n | K9: n | L9: n
A10: ATEAM-27857 | B10: 나챗방 관련 코드 분리(기능/동작 변화 없음) - 나챗방 관련한 리그레션 수행 후 이슈 없으면 클로즈 | J10: n | K10: n | L10: n
A11: ITEAM-32917

Sheet UpdateTest_26.6.0
A2: 분류1 | B2: 분류2 | C2: 분류3 | D2: 분류4 (기능) | E2: 사전 조건 | F2: Test Step (체크할 항목) | G2: iOS | M2: Android | AE2: Comment & Jira | AF2: Spec & Tip | AG2: TC Review
G3: 신규 설치 | J3: 업데이트 | M3: 신규 설치 | T3: 업데이트 | AA3: {Iter} | AB3: 분류
G4: i17 | H4: i18 | I4: i26 | J4: i17 | K4: i18 | L4: i26 | M4: a10 | N4: a11 | O4: a12 | P4: a13 | Q4: a14 | R4: a15 | S4: a16 | T4: a10 | U4: a11 | V4: a12 | W4: a13 | X4: a14 | Y4: a15 | Z4: a16 | AA4: {env} | AB4: =countif(AB7:AB35, ">0") -> 27 | AD4: v25.11.0
G5: i | H5: i | I5: i | J5: o | K5: o | L5: o | M5: 리지 | N5: 엘리 | O5: 아도라 | P5: 미아 | Q5: 제이니 | R5: 유미 | S5: 아몬 | T5: 제론 | U5: 제임슨 | V5: 셀리나 | W5: 로티 | X5: 주아나 | Y5: 보노 | Z5: 글렌 | AA5: {tester} | AC5: T | AD5: V
A6: 테스트 완료 여부
A7: 백업 | B7: 백업/복원 기능 확인 | F7: 구 버전에서 백업 후 신버전에서 복원 (클라우드 무료) * iOS 2026.11.2 버전 테스트 시 - 신규 : 설치 후 기존 계정으로 로그인 정상 동작 하는지 확인 - 업데이트 : 설치 후 기존 계정으로 자동 로그인 정상 동작 하는지 확인 | J7: n | K7: n | L7: n | T7: n | U7: n | V7: n | W7: n | X7: n | Y7: n | Z7: n | AB7: 1 | AC7: app | AD7: v9.6.5
A8: 가입 | B8: 정상 가입 확인 | F8: 정상 가입 검증 조건 - 자동 입력된 전화번호로 자동입력된 인증번호로 가입 완료 - 프로필 사진은 앨범에서 선택 | J8: n | K8: n | L8: n | T8: n | U8: n | V8: n | W8: n | X8: n | Y8: n | Z8: n | AB8: 1 | AC8: app | AD8: v9.6.5
A9: 친구 | B9: 친구 상태 유지 | F9: 구버전에서의 친구 상태가 신버전에서 유지되는지 확인 - 즐겨찾기 - 숨김 - 차단 | G9: n | H9: n | I9: n | M9: n | N9: n | O9: n | P9: n | Q9: n | R9: n | S9: n | AB9: 1 | AC9: app | AD9: v25.9.0
B10: 친구관리 설정값 유지 | F10: 구버전에서의 친구 관리 하위 메뉴 설정값이 신버전에서 유지 및 설정 변경되는지 확인 | G10: n | H10: n | I10: n | M10: n | N10: n | O10: n | P10: n | Q10: n | R10: n | S10: n | AB10: 1 | AC10: app | AD10: v25.9.0
B11: 친구 추가 | F11: 친구 검색 및 추가 동작 확인 | AB11: 1 | AC11: app | AD11: v9.6.5
A12: 프로필 | B12: 내프로필 | F12: - 내프로필 진입 및 편집 기능 동작 확인 ㄴ 편집 완료 후 친구가 내프로필 조회시 편집 반영 ㄴ 프사/배사/상메 등 프로필 요소 변경시 각각 1개의 자동 게시물로 작성되고 & 프로필 홈의 피드로 표시됨 - 내프로필의 구성요소 표시 및 동작 확인 ㄴ 인티커 공감 확인 / 뱃지 등 | AB12: 1 | AC12: app | AD12: v25.9.0
B13: 친구의 프로필 | F13: 친구프로필 내 버튼 표시와 랜딩 확인 - 선물하기 - 송금 - 더보기 ㄴ 메뉴 진입 및 기능 동작 확인 | AB13: 1 | AC13: app | AD13: v25.9.0
B14: 멀티프로필 | F14: 멀프 생성 및 관리 기능 동작 확인 (생성 및 관리 진입점 = 친구탭> 설정> 멀티프로필) | AB14: 1 | AC14: app | AD14: v25.9.0
A15: 채팅 | B15: 일반채팅방 (1:1/그룹) | F15: 모든 타입의 메세지가 유지(전송)되는지 확인 - +메뉴 내 기능들 (사진의 경우 GIF 포함) - 텍스트 ㄴ 텍스트+이모티콘 ㄴ 장문(500자, 4천자 이상) ㄴ 모삭, 전삭 | AB15: 1 | AC15: app | AD15: v25.11.0
B16: 팀채팅방 | F16: 모든 타입의 메세지가 유지(전송)되는지 확인 - +메뉴 내 기능들 (사진의 경우 GIF 포함) - 텍스트(텍스트+이모티콘 / 장문(500자, 4천자 이상) / 모삭, 전삭 / 가리기 / 수정) - (팀데이터 ON 상태) 팀채팅 진입 시, 이전 대화 복원 동작 확인 | AB16: 1 | AC16: app | AD16: v9.6.5
B17: 비밀채팅방 | F17: 모든 타입의 메세지가 유지(전송)되는지 확인 - +메뉴 내 기능들 (사진의 경우 GIF 포함) - 텍스트(텍스트+이모티콘 / 장문(500자)) | AB17: 1 | AC17: app | AD17: v9.6.5
B18: 오픈채팅방 | F18: 모든 타입의 메세지가 유지(전송)되는지 확인 - +메뉴 내 기능들 (사진의 경우 GIF 포함) - 텍스트(텍스트+이모티콘 / 장문(500자) / 모삭, 전삭 / 수정) - 샵검색 | AB18: 1 | AC18: app | AD18: v9.6.5
B19: 사이드메뉴 | F19: 사이드 메뉴 내 기능 및 서비스가 유지(설정/반영)되는지 확인 - 사진/동영상 - 파일 - 링크 - 일정 - 톡게시판 / 공지 / 투표 / 통화(채팅방별 통화 이력) - 챗봇 (테스트 범위 아님) - 그외 사이드메뉴 내 기능 (나가기, 알림, 즐찾, 설정 등) | AB19: 1 | AC19: app | AD19: v25.9.0
B20: 보톡/페톡 | F20: 보톡/페톡 통화가 정상 동작하는지 확인 | AB20: 1 | AC20: app | AD20: v25.9.0 | AF20: yon and, ios 페이스톡 전환 시 검은 화면 (노운이슈)
A21: 채팅목록 | B21: 핀 및 채팅방정렬 | F21: 확인할 내용 - 구버전에서 설정한 핀 및 채팅방 정렬 방법이 신버전에서 유지되는가 - 신버전에서 설정이 변경되는가 | AB21: 1 | AC21: app | AD21: v25.4.0
A22: 설정 | B22: 암호잠금 | F22: 암호잠금 설정이 유지(설정)되는지 확인 | AB22: 1 | AC22: app | AD22: v9.6.5
B23: 알림 | F23: 알림 하위 메뉴들의 설정이 유지(설정)되는지 확인 - 알림음 - 키워드 알림 등 | AB23: 1 | AC23: app | AD23: v11.0.0 | AF23: 2024/6 키워드 알림 Android only 제거 2025/2 ITEAM-28999 비밀채팅방에서는 키워드 알림이 기본 알림음으로 송출됨
B24: 탈퇴 | F24: 탈퇴 동작 확인 | AB24: 1 | AC24: app | AD24: v9.6.5
A25: 기타 | B25: 디버그 메뉴 미노출 확인 | F25: 최종 테스트 빌드에 디버그 메뉴가 미노출되는지 확인 (메뉴 일부만 확인) - 메뉴 노출 위치 참고 : https://wiki.daumkakao.com/pages/viewpage.action?pageId=1243917894 [Android] - 로그인 화면 > 상단 빌드/서버도메인/도메인 - 앱 상단 빌드명 - 더보기 설정 > Debug 메뉴 - 챗로그 롱탭 & 채팅방 +메뉴 > Debug 메뉴 [iOS] - 로그인 화면 > Log console 및 서브 디바이스 로그인 버튼 - 앱 상단 빌드 커밋명 - 더보기 설정 / 채팅방 설정 > development 메뉴 - 챗로그 롱탭 > CBT 메뉴 | AB25: 1 | AC25: app | AD25: v10.4.0
B26: iOS only) 크래시 로그 확인 (QA가 직접 진행) | F26: 1. 톡실행 > ID로 추가 > 카카오톡 ID란에 아래 텍스트 입력하고 검색 ##forcecrash## 2. 크래시가 발생하는지 확인(크래시가 발생 되어야 함), 톡을 재실행 (재실행해야 크래시가 업로드) 3. 1, 2번을 총 3회 실행 (디바이스, ios에 관계없이 1, 2번을 3회 세트로 한번만 해주시면 됩니다.) 4. 로그 확인 https://wiki.daumkakao.com/pages/viewpage.action?pageId=914550563 참고 | G26: n | H26: n | J26: n | K26: n | L26: n | M26: n | N26: n | O26: n | P26: n | Q26: n | R26: n | S26: n | T26: n | U26: n | V26: n | W26: N | X26: N | Y26: N | Z26: N | AB26: 1 | AC26: I | AD26: v9.8.0 | AF26: [aren] 앱스토어에 업로드하는 최종 빌드에서 크래시가 정상적으로 업로드 되는지 확인이 필요하여 추가한 케이스. 본 항목은 QA 가 직접 진행한 후 마킹 합니다. related Jira, Wiki
B27: Android only) 빌드명 [NO_RELEASE] 태그 미노출 확인 | F27: Appcenter > 구글 빌드명 앞에 [NO_RELEASE] 태그가 미노출 되는지 확인 - 최종빌드 화면에서 확인하는 내용으로 모바일 디바이스와는 무관 - 확인 결과는 Android 최신 OS버전 란에 기재 [참고] 태그가 있어 문제가 되는 빌드의 예 https://mobil.daumkakao.io/#/app/600/build/315677 | G27: n | H27: n | I27: n | J27: n | K27: n | L27: n | M27: n | N27: n | O27: n | P27: n | Q27: n | R27: n | S27: n | T27: n | U27: n | V27: n | W27: n | X27: n | Y27: n | AB27: 1 | AC27: A | AD27: v26.3.0
B28: Android only) 빌드명 (PAY_SNAPSHOT) 태그 미노출 확인 | F28: Appcenter > 구글 빌드명 앞에 (PAY_SNAPSHOT) 태그가 미노출 되는지 확인 - 최종빌드 화면에서 확인하는 내용으로 모바일 디바이스와는 무관 - 확인 결과는 Android 최신 OS버전 란에 기재 [참고] 태그가 있어 문제가 되는 빌드의 예 https://appcenter.onkakao.net/apps/43e0fa01-f36e-4df4-bee0-941dd7f22bed/releases/6913 | G28: n | H28: n | I28: n | J28: n | K28: n | L28: n | M28: n | N28: n | O28: n | P28: n | Q28: n | R28: n | S28: n | T28: n | U28: n | V28: n | W28: n | X28: n | Y28: n | AB28: 1 | AC28: A | AD28: v26.3.0
A29: Android PFD 테스트 - 업데이트 테스트 별개로 진행함. (Wiki 참조) 테스트 시점은 업데이트 테스트 종료 이후 Play Store 내부 테스트에 업로드(=서밋 완료) 이후 진행 (안드 당번 QA가 테스트 시점 공유) | T29: D 설치 | U29: D 미설치 | V29: D 설치 | W29: D 미설치 | X29: D 설치 | Y29: D 미설치 | Z29: D 설치 | AB29: - | AC29: - | AE29: PFD 테스트 공통 정보 1. 업데이트 테스트에서, 이전 버전에서 PFD가 설치된 경우 설치가 발생하지 않을수 있음. 이 경우 해당 모듈이 실행되면 Pass 2. 업데이트 테스트에서, 이전 버전에서 PFD가 설치되었어도 PFD가 버전업된 경우 다시 다운로드 진행됨. 이 경우에도 해당 모듈이 정상 실행되면 Pass
A30: PFD 다운로드 & 설치 | B30: 미디어필터 | F30: 미디어필터 PFD 다운로드 및 설치 확인 아래의 접근 경로 중 1곳을 선택하여 미디어필터 실행 (OS별로 중복되지 않도록 진행) - 채팅방 > 플러스버튼 > 사진 동영상 편집 등 (A10, A15) - 채팅방 설정 > 채팅방 프로필 변경 > 사진 편집모드 (A12) - 채팅방 게시판 > 게시판/투표 등 글작성 > 사진 편집모드 (A14) - 친구탭/설정 > 프로필/프로필 배경 편집 > 사진/동영상 편집모드 (A11, A16) - 친구탭/설정 > 멀티 프로필/프로필 배경 편집 > 사진/동영상 편집모드(A13) | G30: n | H30: n | I30: n | J30: n | K30: n | L30: n | AB30: 1 | AC30: A | AD30: v10.1.5 | AE30: (lizzyy, 26/04) Android > [특정단말] PFD 다운로드 & 설치 후 직접 찍은 동영상 필터 적용 > 채팅방 전송 시 오류 발생하며 전송 불가한 현상 QATEAM-12664
B31: 지도 | F31: 지도 SDK PFD 다운로드 및 설치 확인 아래의 접근 경로 중 1곳을 선택하여 지도 SDK 실행 (OS별로 중복되지 않도록 진행) - 채팅방 > 플러스버튼 > 지도 선택 (A10, A12, A14, A16) - 채팅방 > 말풍선 > 지도 이미지 클릭 (지도 이미지는 PFD와 관련없이 노출됨) - 채널 홈 > 장소 정보 클릭시 (A11, A13, A15) 지도 말풍선 랜딩 변경 (채팅방 말풍선 선택 시) - 카맵 설치: 카맵 전환 - 카맵 미설치: 인앱브라우저 오픈 | G31: n | H31: n | I31: n | J31: n | K31: n | L31: n | AB31: 1 | AC31: A | AD31: v25.7.2 | AG31: _x0008_ex)채널홈 : 한신포차
B32: 앱별언어 | F32: 앱별 언어 설치 PFD 다운로드 및 설치 확인 (Android 13 이상) - 톡설정 > 언어 > 미설치 언어 선택 | G32: n | H32: n | I32: n | J32: n | K32: n | L32: n | M32: n | N32: n | O32: n | T32: n | U32: n | V32: n | AB32: 1 | AC32: A | AD32: v10.1.5 | AG32: (bono,2024/2) 언어 불러오기 (미설치 언어 동시에 설치됨)
B33: 테마 | F33: 공식 테마 PFD 다운로드 및 설치 확인 (2024/4차 부터) - 톡설정 > 테마 > 공식테마 다운로드(설치) > 라디오 버튼 변경 - 해당 테마 적용 확인 > 정상 적용 - 플레이스토어로 설치 및 적용된 기존 테마와 별도 동작 (포비 유닛 확인) ㄴ 공식테마 스토어에서 내려간 상태로 위 케이스는 skip - 테마 적용시 앱 재시작 (재시작 이후 전체설정 접근한 탭으로 랜딩) | G33: n | H33: n | I33: n | J33: n | K33: n | L33: n | M33: 고대비 | N33: 비밀의숲 | O33: 제이지 | P33: 콘 | Q33: 숨박꼭질 | R33: 무지 | S33: 여름이야기 | T33: 콘 | U33: 제이지 | V33: 어피치 | W33: 라이언 | X33: 겨울이야기 | Y33: 블랙 | Z33: 여름이야기 | AB33: 1 | AC33: A | AD33: v10.8.0 | AF33: (ellie, 24/8) 플레이 스토어 설치 부분 테스트 제외 플레이 스토어에서 10/14일 이후로 카카오톡 공식테마 미지원 (마켓에서 공식테마 검색 안됨)
B34: 페이스톡 필터 | F34: 페이스톡 화면 꾸미기 PFD 다운로드 및 설치 확인 - 페이스톡 통화> [효과]> [배경]> 아이템 선택 (A10, A12, A14, A16) - 페이스톡 통화> [효과]> [영상 효과]> 아이템 선택 (A11, A13, A15) | G34: n | H34: n | I34: n | J34: n | K34: n | L34: n | AB34: 1 | AC34: A | AD34: _x0008_v11.4.0
A35: 셀 추가시 이 라인 위에서 추가해서 사용하세요. | AB35: - | AC35: - | AD35: -
F37: Iteration | G37: 신규 설치 | J37: 업데이트 | M37: 신규 설치 | T37: 업데이트 | AA37: =AA3 -> {Iter} | AB37: -
F38: 환경 (테스트 수행) | G38: =G4 -> i17 | H38: =H4 -> i18 | I38: =I4 -> i26 | J38: =J4 -> i17 | K38: =K4 -> i18 | L38: =L4 -> i26 | M38: =M4 -> a10 | N38: =N4 -> a11 | ... AA38: =AA4 -> {env} | AB38: total
F39: coverage | G39: =IF(G41-G45, (SUM(G42:G45)-G45)/(G41-G45), 0) -> 0 | H39: =IF(H41-H45, (SUM(H42:H45)-H45)/(H41-H45), 0) -> 0 | I39: =IF(I41-I45, (SUM(I42:I45)-I45)/(I41-I45), 0) -> 0 | J39: =IF(J41-J45, (SUM(J42:J45)-J45)/(J41-J45), 0) -> 0 | K39: =IF(K41-K45, (SUM(K42:K45)-K45)/(K41-K45), 0) -> 0 | L39: =IF(L41-L45, (SUM(L42:L45)-L45)/(L41-L45), 0) -> 0 | M39: =IF(M41-M45, (SUM(M42:M45)-M45)/(M41-M45), 0) -> 0 | N39: =IF(N41-N45, (SUM(N42:N45)-N45)/(N41-N45), 0) -> 0 | ... AA39: =IF(AA41-AA45, (SUM(AA42:AA45)-AA45)/(AA41-AA45), 0) -> 0 | AB39: =sum(K39:AA39)/counta(K39:AA39) -> 0
F40: pass rate | G40: =if((G41-G46-G45), G42/(G41-G46-G45), 0) -> 0 | H40: =if((H41-H46-H45), H42/(H41-H46-H45), 0) -> 0 | I40: =if((I41-I46-I45), I42/(I41-I46-I45), 0) -> 0 | J40: =if((J41-J46-J45), J42/(J41-J46-J45), 0) -> 0 | K40: =if((K41-K46-K45), K42/(K41-K46-K45), 0) -> 0 | L40: =if((L41-L46-L45), L42/(L41-L46-L45), 0) -> 0 | M40: =if((M41-M46-M45), M42/(M41-M46-M45), 0) -> 0 | N40: =if((N41-N46-N45), N42/(N41-N46-N45), 0) -> 0 | ... AA40: =if((AA41-AA46-AA45), AA42/(AA41-AA46-AA45), 0) -> 0 | AB40: =sum(K40:AA40)/counta(K40:AA40) -> 0
F41: total | G41: =countif($AB7:$AB35,"<=1") -> 27 | H41: =countif($AB7:$AB35,"<=1") -> 27 | I41: =countif($AB7:$AB35,"<=1") -> 27 | J41: =countif($AB7:$AB35,"<=1") -> 27 | K41: =countif($AB7:$AB35,"<=1") -> 27 | L41: =countif($AB7:$AB35,"<=1") -> 27 | M41: =countif($AB7:$AB35,"<=1") -> 27 | N41: =countif($AB7:$AB35,"<=1") -> 27 | ... P41: =countif($AB7:$AB35,"<=1") -> 27 | Q41: =countif($AB7:$AB35,"<=3") -> 27 | R41: =countif($AB7:$AB35,"<=3") -> 27 | S41: =countif($AB7:$AB35,"<=3") -> 27 | T41: =countif($AB7:$AB35,"<=3") -> 27 | U41: =countif($AB7:$AB35,"<=3") -> 27 | V41: =countif($AB7:$AB35,"<=3") -> 27 | W41: =countif($AB7:$AB35,"<=3") -> 27 | X41: =countif($AB7:$AB35,"<=3") -> 27 | ... AA41: =countif($AB7:$AB35,"<=3") -> 27 | AB41: =sum(K41:AA41) -> 459
F42: p | G42: =COUNTIF(G7:G35,"p") -> 0 | H42: =COUNTIF(H7:H35,"p") -> 0 | I42: =COUNTIF(I7:I35,"p") -> 0 | J42: =COUNTIF(J7:J35,"p") -> 0 | K42: =COUNTIF(K7:K35,"p") -> 0 | L42: =COUNTIF(L7:L35,"p") -> 0 | M42: =COUNTIF(M7:M35,"p") -> 0 | N42: =COUNTIF(N7:N35,"p") -> 0 | ... AA42: =COUNTIF(AA7:AA35,"p") -> 0 | AB42: =sum(K42:AA42) -> 0
...

Sheet 결과
B1: 전체 통계
B2: OS | C2: 구분 (시트이름) | D2: Iteration | E2: 환경 | F2: Coverage | G2: Pass Rate | H2: Total | I2: P | J2: F | K2: B | L2: N/I | M2: N/R | O2: 비고 | Q2: 전체 통계는 하단 시트별 통계를 취합하여 자동 노출됩니다. 배경이 흰색인 셀은 값을 변경하여 필터링된 통계로 볼 수 있습니다. 그외 셀은 수정하지 마세요.
B3: =IFERROR(VLOOKUP($E3, '입력값'!$B:$C, 2, FALSE),"") -> Android | D3: 6 | E3: a15 | F3: =IF(H3-L3, (H3-L3-M3)/(H3-L3), 0) -> 0 | G3: =if((H3-L3-M3), I3/(H3-L3-M3), 0) -> 0 | H3: =IF(ISBLANK($C$3), SUMIFS(H$30:H632, $E$30:$E632, $E3, $D$30:$D632, $D3), SUMIFS(H$30:H632, $E$30:$E632, $E3, $D$30:$D632, $D3, $C$30:$C632, $C3)) -> 1810 | I3: =IF(ISBLANK($C$3), SUMIFS(I$30:I632, $E$30:$E632, $E3, $D$30:$D632, $D3), SUMIFS(I$30:I632, $E$30:$E632, $E3, $D$30:$D632, $D3, $C$30:$C632, $C3)) -> 0 | J3: =IF(ISBLANK($C$3), SUMIFS(J$30:J632, $E$30:$E632, $E3, $D$30:$D632, $D3), SUMIFS(J$30:J632, $E$30:$E632, $E3, $D$30:$D632, $D3, $C$30:$C632, $C3)) -> 0 | K3: =IF(ISBLANK($C$3), SUMIFS(K$30:K632, $E$30:$E632, $E3, $D$30:$D632, $D3), SUMIFS(K$30:K632, $E$30:$E632, $E3, $D$30:$D632, $D3, $C$30:$C632, $C3)) -> 0 | L3: =IF(ISBLANK($C$3), SUMIFS(L$30:L632, $E$30:$E632, $E3, $D$30:$D632, $D3), SUMIFS(L$30:L632, $E$30:$E632, $E3, $D$30:$D632, $D3, $C$30:$C632, $C3)) -> 74 | M3: =IF(ISBLANK($C$3), SUMIFS(M$30:M632, $E$30:$E632, $E3, $D$30:$D632, $D3), SUMIFS(M$30:M632, $E$30:$E632, $E3, $D$30:$D632, $D3, $C$30:$C632, $C3)) -> 1736
B4: =IFERROR(VLOOKUP($E4, '입력값'!$B:$C, 2, FALSE),"") -> Android | C4: =IF($C$3 = "{시트명 입력}", "", $C$3) | D4: 6 | E4: a16 | F4: =IF(H4-L4, (H4-L4-M4)/(H4-L4), 0) -> 0 | G4: =if((H4-L4-M4), I4/(H4-L4-M4), 0) -> 0 | H4: =IF(ISBLANK($C$3), SUMIFS(H$30:H632, $E$30:$E632, $E4, $D$30:$D632, $D4), SUMIFS(H$30:H632, $E$30:$E632, $E4, $D$30:$D632, $D4, $C$30:$C632, $C4)) -> 2128 | I4: =IF(ISBLANK($C$3), SUMIFS(I$30:I632, $E$30:$E632, $E4, $D$30:$D632, $D4), SUMIFS(I$30:I632, $E$30:$E632, $E4, $D$30:$D632, $D4, $C$30:$C632, $C4)) -> 0 | J4: =IF(ISBLANK($C$3), SUMIFS(J$30:J632, $E$30:$E632, $E4, $D$30:$D632, $D4), SUMIFS(J$30:J632, $E$30:$E632, $E4, $D$30:$D632, $D4, $C$30:$C632, $C4)) -> 0 | K4: =IF(ISBLANK($C$3), SUMIFS(K$30:K632, $E$30:$E632, $E4, $D$30:$D632, $D4), SUMIFS(K$30:K632, $E$30:$E632, $E4, $D$30:$D632, $D4, $C$30:$C632, $C4)) -> 0 | L4: =IF(ISBLANK($C$3), SUMIFS(L$30:L632, $E$30:$E632, $E4, $D$30:$D632, $D4), SUMIFS(L$30:L632, $E$30:$E632, $E4, $D$30:$D632, $D4, $C$30:$C632, $C4)) -> 40 | M4: =IF(ISBLANK($C$3), SUMIFS(M$30:M632, $E$30:$E632, $E4, $D$30:$D632, $D4), SUMIFS(M$30:M632, $E$30:$E632, $E4, $D$30:$D632, $D4, $C$30:$C632, $C4)) -> 2088
B5: =IFERROR(VLOOKUP($E5, '입력값'!$B:$C, 2, FALSE),"") -> iOS | C5: =IF($C$3 = "{시트명 입력}", "", $C$3) | D5: 6 | E5: i26 | F5: =IF(H5-L5, (H5-L5-M5)/(H5-L5), 0) -> 0 | G5: =if((H5-L5-M5), I5/(H5-L5-M5), 0) -> 0 | H5: =IF(ISBLANK($C$3), SUMIFS(H$30:H632, $E$30:$E632, $E5, $D$30:$D632, $D5), SUMIFS(H$30:H632, $E$30:$E632, $E5, $D$30:$D632, $D5, $C$30:$C632, $C5)) -> 1810 | I5: =IF(ISBLANK($C$3), SUMIFS(I$30:I632, $E$30:$E632, $E5, $D$30:$D632, $D5), SUMIFS(I$30:I632, $E$30:$E632, $E5, $D$30:$D632, $D5, $C$30:$C632, $C5)) -> 0 | J5: =IF(ISBLANK($C$3), SUMIFS(J$30:J632, $E$30:$E632, $E5, $D$30:$D632, $D5), SUMIFS(J$30:J632, $E$30:$E632, $E5, $D$30:$D632, $D5, $C$30:$C632, $C5)) -> 0 | K5: =IF(ISBLANK($C$3), SUMIFS(K$30:K632, $E$30:$E632, $E5, $D$30:$D632, $D5), SUMIFS(K$30:K632, $E$30:$E632, $E5, $D$30:$D632, $D5, $C$30:$C632, $C5)) -> 0 | L5: =IF(ISBLANK($C$3), SUMIFS(L$30:L632, $E$30:$E632, $E5, $D$30:$D632, $D5), SUMIFS(L$30:L632, $E$30:$E632, $E5, $D$30:$D632, $D5, $C$30:$C632, $C5)) -> 67 | M5: =IF(ISBLANK($C$3), SUMIFS(M$30:M632, $E$30:$E632, $E5, $D$30:$D632, $D5), SUMIFS(M$30:M632, $E$30:$E632, $E5, $D$30:$D632, $D5, $C$30:$C632, $C5)) -> 1743
B6: =IFERROR(VLOOKUP($E6, '입력값'!$B:$C, 2, FALSE),"") -> iOS | C6: =IF($C$3 = "{시트명 입력}", "", $C$3) | D6: 6 | E6: i18 | F6: =IF(H6-L6, (H6-L6-M6)/(H6-L6), 0) -> 0 | G6: =if((H6-L6-M6), I6/(H6-L6-M6), 0) -> 0 | H6: =IF(ISBLANK($C$3), SUMIFS(H$30:H632, $E$30:$E632, $E6, $D$30:$D632, $D6), SUMIFS(H$30:H632, $E$30:$E632, $E6, $D$30:$D632, $D6, $C$30:$C632, $C6)) -> 2128 | I6: =IF(ISBLANK($C$3), SUMIFS(I$30:I632, $E$30:$E632, $E6, $D$30:$D632, $D6), SUMIFS(I$30:I632, $E$30:$E632, $E6, $D$30:$D632, $D6, $C$30:$C632, $C6)) -> 0 | J6: =IF(ISBLANK($C$3), SUMIFS(J$30:J632, $E$30:$E632, $E6, $D$30:$D632, $D6), SUMIFS(J$30:J632, $E$30:$E632, $E6, $D$30:$D632, $D6, $C$30:$C632, $C6)) -> 0 | K6: =IF(ISBLANK($C$3), SUMIFS(K$30:K632, $E$30:$E632, $E6, $D$30:$D632, $D6), SUMIFS(K$30:K632, $E$30:$E632, $E6, $D$30:$D632, $D6, $C$30:$C632, $C6)) -> 0 | L6: =IF(ISBLANK($C$3), SUMIFS(L$30:L632, $E$30:$E632, $E6, $D$30:$D632, $D6), SUMIFS(L$30:L632, $E$30:$E632, $E6, $D$30:$D632, $D6, $C$30:$C632, $C6)) -> 39 | M6: =IF(ISBLANK($C$3), SUMIFS(M$30:M632, $E$30:$E632, $E6, $D$30:$D632, $D6), SUMIFS(M$30:M632, $E$30:$E632, $E6, $D$30:$D632, $D6, $C$30:$C632, $C6)) -> 2089
B7: =IFERROR(VLOOKUP($E7, '입력값'!$B:$C, 2, FALSE),"") | C7: =IF($C$3 = "{시트명 입력}", "", $C$3) | F7: =IF(H7-L7, (H7-L7-M7)/(H7-L7), 0) -> 0 | G7: =if((H7-L7-M7), I7/(H7-L7-M7), 0) -> 0 | H7: =IF(ISBLANK($C$3), SUMIFS(H$30:H632, $E$30:$E632, $E7, $D$30:$D632, $D7), SUMIFS(H$30:H632, $E$30:$E632, $E7, $D$30:$D632, $D7, $C$30:$C632, $C7)) -> 0 | I7: =IF(ISBLANK($C$3), SUMIFS(I$30:I632, $E$30:$E632, $E7, $D$30:$D632, $D7), SUMIFS(I$30:I632, $E$30:$E632, $E7, $D$30:$D632, $D7, $C$30:$C632, $C7)) -> 0 | J7: =IF(ISBLANK($C$3), SUMIFS(J$30:J632, $E$30:$E632, $E7, $D$30:$D632, $D7), SUMIFS(J$30:J632, $E$30:$E632, $E7, $D$30:$D632, $D7, $C$30:$C632, $C7)) -> 0 | K7: =IF(ISBLANK($C$3), SUMIFS(K$30:K632, $E$30:$E632, $E7, $D$30:$D632, $D7), SUMIFS(K$30:K632, $E$30:$E632, $E7, $D$30:$D632, $D7, $C$30:$C632, $C7)) -> 0 | L7: =IF(ISBLANK($C$3), SUMIFS(L$30:L632, $E$30:$E632, $E7, $D$30:$D632, $D7), SUMIFS(L$30:L632, $E$30:$E632, $E7, $D$30:$D632, $D7, $C$30:$C632, $C7)) -> 0 | M7: =IF(ISBLANK($C$3), SUMIFS(M$30:M632, $E$30:$E632, $E7, $D$30:$D632, $D7), SUMIFS(M$30:M632, $E$30:$E632, $E7, $D$30:$D632, $D7, $C$30:$C632, $C7)) -> 0
B8: =IFERROR(VLOOKUP($E8, '입력값'!$B:$C, 2, FALSE),"") | C8: =IF($C$3 = "{시트명 입력}", "", $C$3) | F8: =IF(H8-L8, (H8-L8-M8)/(H8-L8), 0) -> 0 | G8: =if((H8-L8-M8), I8/(H8-L8-M8), 0) -> 0 | H8: =IF(ISBLANK($C$3), SUMIFS(H$30:H632, $E$30:$E632, $E8, $D$30:$D632, $D8), SUMIFS(H$30:H632, $E$30:$E632, $E8, $D$30:$D632, $D8, $C$30:$C632, $C8)) -> 0 | I8: =IF(ISBLANK($C$3), SUMIFS(I$30:I632, $E$30:$E632, $E8, $D$30:$D632, $D8), SUMIFS(I$30:I632, $E$30:$E632, $E8, $D$30:$D632, $D8, $C$30:$C632, $C8)) -> 0 | J8: =IF(ISBLANK($C$3), SUMIFS(J$30:J632, $E$30:$E632, $E8, $D$30:$D632, $D8), SUMIFS(J$30:J632, $E$30:$E632, $E8, $D$30:$D632, $D8, $C$30:$C632, $C8)) -> 0 | K8: =IF(ISBLANK($C$3), SUMIFS(K$30:K632, $E$30:$E632, $E8, $D$30:$D632, $D8), SUMIFS(K$30:K632, $E$30:$E632, $E8, $D$30:$D632, $D8, $C$30:$C632, $C8)) -> 0 | L8: =IF(ISBLANK($C$3), SUMIFS(L$30:L632, $E$30:$E632, $E8, $D$30:$D632, $D8), SUMIFS(L$30:L632, $E$30:$E632, $E8, $D$30:$D632, $D8, $C$30:$C632, $C8)) -> 0 | M8: =IF(ISBLANK($C$3), SUMIFS(M$30:M632, $E$30:$E632, $E8, $D$30:$D632, $D8), SUMIFS(M$30:M632, $E$30:$E632, $E8, $D$30:$D632, $D8, $C$30:$C632, $C8)) -> 0
B9: =IFERROR(VLOOKUP($E9, '입력값'!$B:$C, 2, FALSE),"") | C9: =IF($C$3 = "{시트명 입력}", "", $C$3) | F9: =IF(H9-L9, (H9-L9-M9)/(H9-L9), 0) -> 0 | G9: =if((H9-L9-M9), I9/(H9-L9-M9), 0) -> 0 | H9: =IF(ISBLANK($C$3), SUMIFS(H$30:H632, $E$30:$E632, $E9, $D$30:$D632, $D9), SUMIFS(H$30:H632, $E$30:$E632, $E9, $D$30:$D632, $D9, $C$30:$C632, $C9)) -> 0 | I9: =IF(ISBLANK($C$3), SUMIFS(I$30:I632, $E$30:$E632, $E9, $D$30:$D632, $D9), SUMIFS(I$30:I632, $E$30:$E632, $E9, $D$30:$D632, $D9, $C$30:$C632, $C9)) -> 0 | J9: =IF(ISBLANK($C$3), SUMIFS(J$30:J632, $E$30:$E632, $E9, $D$30:$D632, $D9), SUMIFS(J$30:J632, $E$30:$E632, $E9, $D$30:$D632, $D9, $C$30:$C632, $C9)) -> 0 | K9: =IF(ISBLANK($C$3), SUMIFS(K$30:K632, $E$30:$E632, $E9, $D$30:$D632, $D9), SUMIFS(K$30:K632, $E$30:$E632, $E9, $D$30:$D632, $D9, $C$30:$C632, $C9)) -> 0 | L9: =IF(ISBLANK($C$3), SUMIFS(L$30:L632, $E$30:$E632, $E9, $D$30:$D632, $D9), SUMIFS(L$30:L632, $E$30:$E632, $E9, $D$30:$D632, $D9, $C$30:$C632, $C9)) -> 0 | M9: =IF(ISBLANK($C$3), SUMIFS(M$30:M632, $E$30:$E632, $E9, $D$30:$D632, $D9), SUMIFS(M$30:M632, $E$30:$E632, $E9, $D$30:$D632, $D9, $C$30:$C632, $C9)) -> 0
B10: =IFERROR(VLOOKUP($E10, '입력값'!$B:$C, 2, FALSE),"") | C10: =IF($C$3 = "{시트명 입력}", "", $C$3) | F10: =IF(H10-L10, (H10-L10-M10)/(H10-L10), 0) -> 0 | G10: =if((H10-L10-M10), I10/(H10-L10-M10), 0) -> 0 | H10: =IF(ISBLANK($C$3), SUMIFS(H$30:H632, $E$30:$E632, $E10, $D$30:$D632, $D10), SUMIFS(H$30:H632, $E$30:$E632, $E10, $D$30:$D632, $D10, $C$30:$C632, $C10)) -> 0 | I10: =IF(ISBLANK($C$3), SUMIFS(I$30:I632, $E$30:$E632, $E10, $D$30:$D632, $D10), SUMIFS(I$30:I632, $E$30:$E632, $E10, $D$30:$D632, $D10, $C$30:$C632, $C10)) -> 0 | J10: =IF(ISBLANK($C$3), SUMIFS(J$30:J632, $E$30:$E632, $E10, $D$30:$D632, $D10), SUMIFS(J$30:J632, $E$30:$E632, $E10, $D$30:$D632, $D10, $C$30:$C632, $C10)) -> 0 | K10: =IF(ISBLANK($C$3), SUMIFS(K$30:K632, $E$30:$E632, $E10, $D$30:$D632, $D10), SUMIFS(K$30:K632, $E$30:$E632, $E10, $D$30:$D632, $D10, $C$30:$C632, $C10)) -> 0 | L10: =IF(ISBLANK($C$3), SUMIFS(L$30:L632, $E$30:$E632, $E10, $D$30:$D632, $D10), SUMIFS(L$30:L632, $E$30:$E632, $E10, $D$30:$D632, $D10, $C$30:$C632, $C10)) -> 0 | M10: =IF(ISBLANK($C$3), SUMIFS(M$30:M632, $E$30:$E632, $E10, $D$30:$D632, $D10), SUMIFS(M$30:M632, $E$30:$E632, $E10, $D$30:$D632, $D10, $C$30:$C632, $C10)) -> 0
B11: =IFERROR(VLOOKUP($E11, '입력값'!$B:$C, 2, FALSE),"") | C11: =IF($C$3 = "{시트명 입력}", "", $C$3) | F11: =IF(H11-L11, (H11-L11-M11)/(H11-L11), 0) -> 0 | G11: =if((H11-L11-M11), I11/(H11-L11-M11), 0) -> 0 | H11: =IF(ISBLANK($C$3), SUMIFS(H$30:H632, $E$30:$E632, $E11, $D$30:$D632, $D11), SUMIFS(H$30:H632, $E$30:$E632, $E11, $D$30:$D632, $D11, $C$30:$C632, $C11)) -> 0 | I11: =IF(ISBLANK($C$3), SUMIFS(I$30:I632, $E$30:$E632, $E11, $D$30:$D632, $D11), SUMIFS(I$30:I632, $E$30:$E632, $E11, $D$30:$D632, $D11, $C$30:$C632, $C11)) -> 0 | J11: =IF(ISBLANK($C$3), SUMIFS(J$30:J632, $E$30:$E632, $E11, $D$30:$D632, $D11), SUMIFS(J$30:J632, $E$30:$E632, $E11, $D$30:$D632, $D11, $C$30:$C632, $C11)) -> 0 | K11: =IF(ISBLANK($C$3), SUMIFS(K$30:K632, $E$30:$E632, $E11, $D$30:$D632, $D11), SUMIFS(K$30:K632, $E$30:$E632, $E11, $D$30:$D632, $D11, $C$30:$C632, $C11)) -> 0 | L11: =IF(ISBLANK($C$3), SUMIFS(L$30:L632, $E$30:$E632, $E11, $D$30:$D632, $D11), SUMIFS(L$30:L632, $E$30:$E632, $E11, $D$30:$D632, $D11, $C$30:$C632, $C11)) -> 0 | M11: =IF(ISBLANK($C$3), SUMIFS(M$30:M632, $E$30:$E632, $E11, $D$30:$D632, $D11), SUMIFS(M$30:M632, $E$30:$E632, $E11, $D$30:$D632, $D11, $C$30:$C632, $C11)) -> 0
B12: =IFERROR(VLOOKUP($E12, '입력값'!$B:$C, 2, FALSE),"") | C12: =IF($C$3 = "{시트명 입력}", "", $C$3) | F12: =IF(H12-L12, (H12-L12-M12)/(H12-L12), 0) -> 0 | G12: =if((H12-L12-M12), I12/(H12-L12-M12), 0) -> 0 | H12: =IF(ISBLANK($C$3), SUMIFS(H$30:H632, $E$30:$E632, $E12, $D$30:$D632, $D12), SUMIFS(H$30:H632, $E$30:$E632, $E12, $D$30:$D632, $D12, $C$30:$C632, $C12)) -> 0 | I12: =IF(ISBLANK($C$3), SUMIFS(I$30:I632, $E$30:$E632, $E12, $D$30:$D632, $D12), SUMIFS(I$30:I632, $E$30:$E632, $E12, $D$30:$D632, $D12, $C$30:$C632, $C12)) -> 0 | J12: =IF(ISBLANK($C$3), SUMIFS(J$30:J632, $E$30:$E632, $E12, $D$30:$D632, $D12), SUMIFS(J$30:J632, $E$30:$E632, $E12, $D$30:$D632, $D12, $C$30:$C632, $C12)) -> 0 | K12: =IF(ISBLANK($C$3), SUMIFS(K$30:K632, $E$30:$E632, $E12, $D$30:$D632, $D12), SUMIFS(K$30:K632, $E$30:$E632, $E12, $D$30:$D632, $D12, $C$30:$C632, $C12)) -> 0 | L12: =IF(ISBLANK($C$3), SUMIFS(L$30:L632, $E$30:$E632, $E12, $D$30:$D632, $D12), SUMIFS(L$30:L632, $E$30:$E632, $E12, $D$30:$D632, $D12, $C$30:$C632, $C12)) -> 0 | M12: =IF(ISBLANK($C$3), SUMIFS(M$30:M632, $E$30:$E632, $E12, $D$30:$D632, $D12), SUMIFS(M$30:M632, $E$30:$E632, $E12, $D$30:$D632, $D12, $C$30:$C632, $C12)) -> 0
B13: =IFERROR(VLOOKUP($E13, '입력값'!$B:$C, 2, FALSE),"") | C13: =IF($C$3 = "{시트명 입력}", "", $C$3) | F13: =IF(H13-L13, (H13-L13-M13)/(H13-L13), 0) -> 0 | G13: =if((H13-L13-M13), I13/(H13-L13-M13), 0) -> 0 | H13: =IF(ISBLANK($C$3), SUMIFS(H$30:H632, $E$30:$E632, $E13, $D$30:$D632, $D13), SUMIFS(H$30:H632, $E$30:$E632, $E13, $D$30:$D632, $D13, $C$30:$C632, $C13)) -> 0 | I13: =IF(ISBLANK($C$3), SUMIFS(I$30:I632, $E$30:$E632, $E13, $D$30:$D632, $D13), SUMIFS(I$30:I632, $E$30:$E632, $E13, $D$30:$D632, $D13, $C$30:$C632, $C13)) -> 0 | J13: =IF(ISBLANK($C$3), SUMIFS(J$30:J632, $E$30:$E632, $E13, $D$30:$D632, $D13), SUMIFS(J$30:J632, $E$30:$E632, $E13, $D$30:$D632, $D13, $C$30:$C632, $C13)) -> 0 | K13: =IF(ISBLANK($C$3), SUMIFS(K$30:K632, $E$30:$E632, $E13, $D$30:$D632, $D13), SUMIFS(K$30:K632, $E$30:$E632, $E13, $D$30:$D632, $D13, $C$30:$C632, $C13)) -> 0 | L13: =IF(ISBLANK($C$3), SUMIFS(L$30:L632, $E$30:$E632, $E13, $D$30:$D632, $D13), SUMIFS(L$30:L632, $E$30:$E632, $E13, $D$30:$D632, $D13, $C$30:$C632, $C13)) -> 0 | M13: =IF(ISBLANK($C$3), SUMIFS(M$30:M632, $E$30:$E632, $E13, $D$30:$D632, $D13), SUMIFS(M$30:M632, $E$30:$E632, $E13, $D$30:$D632, $D13, $C$30:$C632, $C13)) -> 0
B14: =IFERROR(VLOOKUP($E14, '입력값'!$B:$C, 2, FALSE),"") | C14: =IF($C$3 = "{시트명 입력}", "", $C$3) | F14: =IF(H14-L14, (H14-L14-M14)/(H14-L14), 0) -> 0 | G14: =if((H14-L14-M14), I14/(H14-L14-M14), 0) -> 0 | H14: =IF(ISBLANK($C$3), SUMIFS(H$30:H632, $E$30:$E632, $E14, $D$30:$D632, $D14), SUMIFS(H$30:H632, $E$30:$E632, $E14, $D$30:$D632, $D14, $C$30:$C632, $C14)) -> 0 | I14: =IF(ISBLANK($C$3), SUMIFS(I$30:I632, $E$30:$E632, $E14, $D$30:$D632, $D14), SUMIFS(I$30:I632, $E$30:$E632, $E14, $D$30:$D632, $D14, $C$30:$C632, $C14)) -> 0 | J14: =IF(ISBLANK($C$3), SUMIFS(J$30:J632, $E$30:$E632, $E14, $D$30:$D632, $D14), SUMIFS(J$30:J632, $E$30:$E632, $E14, $D$30:$D632, $D14, $C$30:$C632, $C14)) -> 0 | K14: =IF(ISBLANK($C$3), SUMIFS(K$30:K632, $E$30:$E632, $E14, $D$30:$D632, $D14), SUMIFS(K$30:K632, $E$30:$E632, $E14, $D$30:$D632, $D14, $C$30:$C632, $C14)) -> 0 | L14: =IF(ISBLANK($C$3), SUMIFS(L$30:L632, $E$30:$E632, $E14, $D$30:$D632, $D14), SUMIFS(L$30:L632, $E$30:$E632, $E14, $D$30:$D632, $D14, $C$30:$C632, $C14)) -> 0 | M14: =IF(ISBLANK($C$3), SUMIFS(M$30:M632, $E$30:$E632, $E14, $D$30:$D632, $D14), SUMIFS(M$30:M632, $E$30:$E632, $E14, $D$30:$D632, $D14, $C$30:$C632, $C14)) -> 0
B15: =IFERROR(VLOOKUP($E15, '입력값'!$B:$C, 2, FALSE),"") | C15: =IF($C$3 = "{시트명 입력}", "", $C$3) | F15: =IF(H15-L15, (H15-L15-M15)/(H15-L15), 0) -> 0 | G15: =if((H15-L15-M15), I15/(H15-L15-M15), 0) -> 0 | H15: =IF(ISBLANK($C$3), SUMIFS(H$30:H632, $E$30:$E632, $E15, $D$30:$D632, $D15), SUMIFS(H$30:H632, $E$30:$E632, $E15, $D$30:$D632, $D15, $C$30:$C632, $C15)) -> 0 | I15: =IF(ISBLANK($C$3), SUMIFS(I$30:I632, $E$30:$E632, $E15, $D$30:$D632, $D15), SUMIFS(I$30:I632, $E$30:$E632, $E15, $D$30:$D632, $D15, $C$30:$C632, $C15)) -> 0 | J15: =IF(ISBLANK($C$3), SUMIFS(J$30:J632, $E$30:$E632, $E15, $D$30:$D632, $D15), SUMIFS(J$30:J632, $E$30:$E632, $E15, $D$30:$D632, $D15, $C$30:$C632, $C15)) -> 0 | K15: =IF(ISBLANK($C$3), SUMIFS(K$30:K632, $E$30:$E632, $E15, $D$30:$D632, $D15), SUMIFS(K$30:K632, $E$30:$E632, $E15, $D$30:$D632, $D15, $C$30:$C632, $C15)) -> 0 | L15: =IF(ISBLANK($C$3), SUMIFS(L$30:L632, $E$30:$E632, $E15, $D$30:$D632, $D15), SUMIFS(L$30:L632, $E$30:$E632, $E15, $D$30:$D632, $D15, $C$30:$C632, $C15)) -> 0 | M15: =IF(ISBLANK($C$3), SUMIFS(M$30:M632, $E$30:$E632, $E15, $D$30:$D632, $D15), SUMIFS(M$30:M632, $E$30:$E632, $E15, $D$30:$D632, $D15, $C$30:$C632, $C15)) -> 0
B16: =IFERROR(VLOOKUP($E16, '입력값'!$B:$C, 2, FALSE),"") | C16: =IF($C$3 = "{시트명 입력}", "", $C$3) | F16: =IF(H16-L16, (H16-L16-M16)/(H16-L16), 0) -> 0 | G16: =if((H16-L16-M16), I16/(H16-L16-M16), 0) -> 0 | H16: =IF(ISBLANK($C$3), SUMIFS(H$30:H632, $E$30:$E632, $E16, $D$30:$D632, $D16), SUMIFS(H$30:H632, $E$30:$E632, $E16, $D$30:$D632, $D16, $C$30:$C632, $C16)) -> 0 | I16: =IF(ISBLANK($C$3), SUMIFS(I$30:I632, $E$30:$E632, $E16, $D$30:$D632, $D16), SUMIFS(I$30:I632, $E$30:$E632, $E16, $D$30:$D632, $D16, $C$30:$C632, $C16)) -> 0 | J16: =IF(ISBLANK($C$3), SUMIFS(J$30:J632, $E$30:$E632, $E16, $D$30:$D632, $D16), SUMIFS(J$30:J632, $E$30:$E632, $E16, $D$30:$D632, $D16, $C$30:$C632, $C16)) -> 0 | K16: =IF(ISBLANK($C$3), SUMIFS(K$30:K632, $E$30:$E632, $E16, $D$30:$D632, $D16), SUMIFS(K$30:K632, $E$30:$E632, $E16, $D$30:$D632, $D16, $C$30:$C632, $C16)) -> 0 | L16: =IF(ISBLANK($C$3), SUMIFS(L$30:L632, $E$30:$E632, $E16, $D$30:$D632, $D16), SUMIFS(L$30:L632, $E$30:$E632, $E16, $D$30:$D632, $D16, $C$30:$C632, $C16)) -> 0 | M16: =IF(ISBLANK($C$3), SUMIFS(M$30:M632, $E$30:$E632, $E16, $D$30:$D632, $D16), SUMIFS(M$30:M632, $E$30:$E632, $E16, $D$30:$D632, $D16, $C$30:$C632, $C16)) -> 0
B17: =IFERROR(VLOOKUP($E17, '입력값'!$B:$C, 2, FALSE),"") | C17: =IF($C$3 = "{시트명 입력}", "", $C$3) | F17: =IF(H17-L17, (H17-L17-M17)/(H17-L17), 0) -> 0 | G17: =if((H17-L17-M17), I17/(H17-L17-M17), 0) -> 0 | H17: =IF(ISBLANK($C$3), SUMIFS(H$30:H632, $E$30:$E632, $E17, $D$30:$D632, $D17), SUMIFS(H$30:H632, $E$30:$E632, $E17, $D$30:$D632, $D17, $C$30:$C632, $C17)) -> 0 | I17: =IF(ISBLANK($C$3), SUMIFS(I$30:I632, $E$30:$E632, $E17, $D$30:$D632, $D17), SUMIFS(I$30:I632, $E$30:$E632, $E17, $D$30:$D632, $D17, $C$30:$C632, $C17)) -> 0 | J17: =IF(ISBLANK($C$3), SUMIFS(J$30:J632, $E$30:$E632, $E17, $D$30:$D632, $D17), SUMIFS(J$30:J632, $E$30:$E632, $E17, $D$30:$D632, $D17, $C$30:$C632, $C17)) -> 0 | K17: =IF(ISBLANK($C$3), SUMIFS(K$30:K632, $E$30:$E632, $E17, $D$30:$D632, $D17), SUMIFS(K$30:K632, $E$30:$E632, $E17, $D$30:$D632, $D17, $C$30:$C632, $C17)) -> 0 | L17: =IF(ISBLANK($C$3), SUMIFS(L$30:L632, $E$30:$E632, $E17, $D$30:$D632, $D17), SUMIFS(L$30:L632, $E$30:$E632, $E17, $D$30:$D632, $D17, $C$30:$C632, $C17)) -> 0 | M17: =IF(ISBLANK($C$3), SUMIFS(M$30:M632, $E$30:$E632, $E17, $D$30:$D632, $D17), SUMIFS(M$30:M632, $E$30:$E632, $E17, $D$30:$D632, $D17, $C$30:$C632, $C17)) -> 0
B18: =IFERROR(VLOOKUP($E18, '입력값'!$B:$C, 2, FALSE),"") | C18: =IF($C$3 = "{시트명 입력}", "", $C$3) | F18: =IF(H18-L18, (H18-L18-M18)/(H18-L18), 0) -> 0 | G18: =if((H18-L18-M18), I18/(H18-L18-M18), 0) -> 0 | H18: =IF(ISBLANK($C$3), SUMIFS(H$30:H632, $E$30:$E632, $E18, $D$30:$D632, $D18), SUMIFS(H$30:H632, $E$30:$E632, $E18, $D$30:$D632, $D18, $C$30:$C632, $C18)) -> 0 | I18: =IF(ISBLANK($C$3), SUMIFS(I$30:I632, $E$30:$E632, $E18, $D$30:$D632, $D18), SUMIFS(I$30:I632, $E$30:$E632, $E18, $D$30:$D632, $D18, $C$30:$C632, $C18)) -> 0 | J18: =IF(ISBLANK($C$3), SUMIFS(J$30:J632, $E$30:$E632, $E18, $D$30:$D632, $D18), SUMIFS(J$30:J632, $E$30:$E632, $E18, $D$30:$D632, $D18, $C$30:$C632, $C18)) -> 0 | K18: =IF(ISBLANK($C$3), SUMIFS(K$30:K632, $E$30:$E632, $E18, $D$30:$D632, $D18), SUMIFS(K$30:K632, $E$30:$E632, $E18, $D$30:$D632, $D18, $C$30:$C632, $C18)) -> 0 | L18: =IF(ISBLANK($C$3), SUMIFS(L$30:L632, $E$30:$E632, $E18, $D$30:$D632, $D18), SUMIFS(L$30:L632, $E$30:$E632, $E18, $D$30:$D632, $D18, $C$30:$C632, $C18)) -> 0 | M18: =IF(ISBLANK($C$3), SUMIFS(M$30:M632, $E$30:$E632, $E18, $D$30:$D632, $D18), SUMIFS(M$30:M632, $E$30:$E632, $E18, $D$30:$D632, $D18, $C$30:$C632, $C18)) -> 0
B19: =IFERROR(VLOOKUP($E19, '입력값'!$B:$C, 2, FALSE),"") | C19: =IF($C$3 = "{시트명 입력}", "", $C$3) | F19: =IF(H19-L19, (H19-L19-M19)/(H19-L19), 0) -> 0 | G19: =if((H19-L19-M19), I19/(H19-L19-M19), 0) -> 0 | H19: =IF(ISBLANK($C$3), SUMIFS(H$30:H632, $E$30:$E632, $E19, $D$30:$D632, $D19), SUMIFS(H$30:H632, $E$30:$E632, $E19, $D$30:$D632, $D19, $C$30:$C632, $C19)) -> 0 | I19: =IF(ISBLANK($C$3), SUMIFS(I$30:I632, $E$30:$E632, $E19, $D$30:$D632, $D19), SUMIFS(I$30:I632, $E$30:$E632, $E19, $D$30:$D632, $D19, $C$30:$C632, $C19)) -> 0 | J19: =IF(ISBLANK($C$3), SUMIFS(J$30:J632, $E$30:$E632, $E19, $D$30:$D632, $D19), SUMIFS(J$30:J632, $E$30:$E632, $E19, $D$30:$D632, $D19, $C$30:$C632, $C19)) -> 0 | K19: =IF(ISBLANK($C$3), SUMIFS(K$30:K632, $E$30:$E632, $E19, $D$30:$D632, $D19), SUMIFS(K$30:K632, $E$30:$E632, $E19, $D$30:$D632, $D19, $C$30:$C632, $C19)) -> 0 | L19: =IF(ISBLANK($C$3), SUMIFS(L$30:L632, $E$30:$E632, $E19, $D$30:$D632, $D19), SUMIFS(L$30:L632, $E$30:$E632, $E19, $D$30:$D632, $D19, $C$30:$C632, $C19)) -> 0 | M19: =IF(ISBLANK($C$3), SUMIFS(M$30:M632, $E$30:$E632, $E19, $D$30:$D632, $D19), SUMIFS(M$30:M632, $E$30:$E632, $E19, $D$30:$D632, $D19, $C$30:$C632, $C19)) -> 0
B20: =IFERROR(VLOOKUP($E20, '입력값'!$B:$C, 2, FALSE),"") | C20: =IF($C$3 = "{시트명 입력}", "", $C$3) | F20: =IF(H20-L20, (H20-L20-M20)/(H20-L20), 0) -> 0 | G20: =if((H20-L20-M20), I20/(H20-L20-M20), 0) -> 0 | H20: =IF(ISBLANK($C$3), SUMIFS(H$30:H632, $E$30:$E632, $E20, $D$30:$D632, $D20), SUMIFS(H$30:H632, $E$30:$E632, $E20, $D$30:$D632, $D20, $C$30:$C632, $C20)) -> 0 | I20: =IF(ISBLANK($C$3), SUMIFS(I$30:I632, $E$30:$E632, $E20, $D$30:$D632, $D20), SUMIFS(I$30:I632, $E$30:$E632, $E20, $D$30:$D632, $D20, $C$30:$C632, $C20)) -> 0 | J20: =IF(ISBLANK($C$3), SUMIFS(J$30:J632, $E$30:$E632, $E20, $D$30:$D632, $D20), SUMIFS(J$30:J632, $E$30:$E632, $E20, $D$30:$D632, $D20, $C$30:$C632, $C20)) -> 0 | K20: =IF(ISBLANK($C$3), SUMIFS(K$30:K632, $E$30:$E632, $E20, $D$30:$D632, $D20), SUMIFS(K$30:K632, $E$30:$E632, $E20, $D$30:$D632, $D20, $C$30:$C632, $C20)) -> 0 | L20: =IF(ISBLANK($C$3), SUMIFS(L$30:L632, $E$30:$E632, $E20, $D$30:$D632, $D20), SUMIFS(L$30:L632, $E$30:$E632, $E20, $D$30:$D632, $D20, $C$30:$C632, $C20)) -> 0 | M20: =IF(ISBLANK($C$3), SUMIFS(M$30:M632, $E$30:$E632, $E20, $D$30:$D632, $D20), SUMIFS(M$30:M632, $E$30:$E632, $E20, $D$30:$D632, $D20, $C$30:$C632, $C20)) -> 0
B21: =IFERROR(VLOOKUP($E21, '입력값'!$B:$C, 2, FALSE),"") | C21: =IF($C$3 = "{시트명 입력}", "", $C$3) | F21: =IF(H21-L21, (H21-L21-M21)/(H21-L21), 0) -> 0 | G21: =if((H21-L21-M21), I21/(H21-L21-M21), 0) -> 0 | H21: =IF(ISBLANK($C$3), SUMIFS(H$30:H632, $E$30:$E632, $E21, $D$30:$D632, $D21), SUMIFS(H$30:H632, $E$30:$E632, $E21, $D$30:$D632, $D21, $C$30:$C632, $C21)) -> 0 | I21: =IF(ISBLANK($C$3), SUMIFS(I$30:I632, $E$30:$E632, $E21, $D$30:$D632, $D21), SUMIFS(I$30:I632, $E$30:$E632, $E21, $D$30:$D632, $D21, $C$30:$C632, $C21)) -> 0 | J21: =IF(ISBLANK($C$3), SUMIFS(J$30:J632, $E$30:$E632, $E21, $D$30:$D632, $D21), SUMIFS(J$30:J632, $E$30:$E632, $E21, $D$30:$D632, $D21, $C$30:$C632, $C21)) -> 0 | K21: =IF(ISBLANK($C$3), SUMIFS(K$30:K632, $E$30:$E632, $E21, $D$30:$D632, $D21), SUMIFS(K$30:K632, $E$30:$E632, $E21, $D$30:$D632, $D21, $C$30:$C632, $C21)) -> 0 | L21: =IF(ISBLANK($C$3), SUMIFS(L$30:L632, $E$30:$E632, $E21, $D$30:$D632, $D21), SUMIFS(L$30:L632, $E$30:$E632, $E21, $D$30:$D632, $D21, $C$30:$C632, $C21)) -> 0 | M21: =IF(ISBLANK($C$3), SUMIFS(M$30:M632, $E$30:$E632, $E21, $D$30:$D632, $D21), SUMIFS(M$30:M632, $E$30:$E632, $E21, $D$30:$D632, $D21, $C$30:$C632, $C21)) -> 0
B22: =IFERROR(VLOOKUP($E22, '입력값'!$B:$C, 2, FALSE),"") | C22: =IF($C$3 = "{시트명 입력}", "", $C$3) | F22: =IF(H22-L22, (H22-L22-M22)/(H22-L22), 0) -> 0 | G22: =if((H22-L22-M22), I22/(H22-L22-M22), 0) -> 0 | H22: =IF(ISBLANK($C$3), SUMIFS(H$30:H632, $E$30:$E632, $E22, $D$30:$D632, $D22), SUMIFS(H$30:H632, $E$30:$E632, $E22, $D$30:$D632, $D22, $C$30:$C632, $C22)) -> 0 | I22: =IF(ISBLANK($C$3), SUMIFS(I$30:I632, $E$30:$E632, $E22, $D$30:$D632, $D22), SUMIFS(I$30:I632, $E$30:$E632, $E22, $D$30:$D632, $D22, $C$30:$C632, $C22)) -> 0 | J22: =IF(ISBLANK($C$3), SUMIFS(J$30:J632, $E$30:$E632, $E22, $D$30:$D632, $D22), SUMIFS(J$30:J632, $E$30:$E632, $E22, $D$30:$D632, $D22, $C$30:$C632, $C22)) -> 0 | K22: =IF(ISBLANK($C$3), SUMIFS(K$30:K632, $E$30:$E632, $E22, $D$30:$D632, $D22), SUMIFS(K$30:K632, $E$30:$E632, $E22, $D$30:$D632, $D22, $C$30:$C632, $C22)) -> 0 | L22: =IF(ISBLANK($C$3), SUMIFS(L$30:L632, $E$30:$E632, $E22, $D$30:$D632, $D22), SUMIFS(L$30:L632, $E$30:$E632, $E22, $D$30:$D632, $D22, $C$30:$C632, $C22)) -> 0 | M22: =IF(ISBLANK($C$3), SUMIFS(M$30:M632, $E$30:$E632, $E22, $D$30:$D632, $D22), SUMIFS(M$30:M632, $E$30:$E632, $E22, $D$30:$D632, $D22, $C$30:$C632, $C22)) -> 0
B23: 부분 | C23: =E23 & (IF(ISBLANK(D23), " (통합)", " (" & D23 & "차)")) -> Android (6차) | D23: 6 | E23: Android | F23: =IF(H23-L23, (H23-L23-M23)/(H23-L23), 0) -> 0 | G23: =if((H23-L23-M23), I23/(H23-L23-M23), 0) -> 0 | H23: =IF(ISBLANK($D23), SUMIFS(H$3:H$22, $B$3:$B$22, $E23), SUMIFS(H$3:H$22, $D$3:$D$22, $D23, $B$3:$B$22, $E23)) -> 3938 | I23: =IF(ISBLANK($D23), SUMIFS(I$3:I$22, $B$3:$B$22, $E23), SUMIFS(I$3:I$22, $D$3:$D$22, $D23, $B$3:$B$22, $E23)) -> 0 | J23: =IF(ISBLANK($D23), SUMIFS(J$3:J$22, $B$3:$B$22, $E23), SUMIFS(J$3:J$22, $D$3:$D$22, $D23, $B$3:$B$22, $E23)) -> 0 | K23: =IF(ISBLANK($D23), SUMIFS(K$3:K$22, $B$3:$B$22, $E23), SUMIFS(K$3:K$22, $D$3:$D$22, $D23, $B$3:$B$22, $E23)) -> 0 | L23: =IF(ISBLANK($D23), SUMIFS(L$3:L$22, $B$3:$B$22, $E23), SUMIFS(L$3:L$22, $D$3:$D$22, $D23, $B$3:$B$22, $E23)) -> 114 | M23: =IF(ISBLANK($D23), SUMIFS(M$3:M$22, $B$3:$B$22, $E23), SUMIFS(M$3:M$22, $D$3:$D$22, $D23, $B$3:$B$22, $E23)) -> 3824
C24: =E24 & (IF(ISBLANK(D24), " (통합)", " (" & D24 & "차)")) -> iOS (6차) | D24: 6 | E24: iOS | F24: =IF(H24-L24, (H24-L24-M24)/(H24-L24), 0) -> 0 | G24: =if((H24-L24-M24), I24/(H24-L24-M24), 0) -> 0 | H24: =IF(ISBLANK($D24), SUMIFS(H$3:H$22, $B$3:$B$22, $E24), SUMIFS(H$3:H$22, $D$3:$D$22, $D24, $B$3:$B$22, $E24)) -> 3938 | I24: =IF(ISBLANK($D24), SUMIFS(I$3:I$22, $B$3:$B$22, $E24), SUMIFS(I$3:I$22, $D$3:$D$22, $D24, $B$3:$B$22, $E24)) -> 0 | J24: =IF(ISBLANK($D24), SUMIFS(J$3:J$22, $B$3:$B$22, $E24), SUMIFS(J$3:J$22, $D$3:$D$22, $D24, $B$3:$B$22, $E24)) -> 0 | K24: =IF(ISBLANK($D24), SUMIFS(K$3:K$22, $B$3:$B$22, $E24), SUMIFS(K$3:K$22, $D$3:$D$22, $D24, $B$3:$B$22, $E24)) -> 0 | L24: =IF(ISBLANK($D24), SUMIFS(L$3:L$22, $B$3:$B$22, $E24), SUMIFS(L$3:L$22, $D$3:$D$22, $D24, $B$3:$B$22, $E24)) -> 106 | M24: =IF(ISBLANK($D24), SUMIFS(M$3:M$22, $B$3:$B$22, $E24), SUMIFS(M$3:M$22, $D$3:$D$22, $D24, $B$3:$B$22, $E24)) -> 3832
C25: =E25 & (IF(ISBLANK(D25), " (통합)", " (" & D25 & "차)")) -> Windows (통합) | E25: Windows | F25: =IF(H25-L25, (H25-L25-M25)/(H25-L25), 0) -> 0 | G25: =if((H25-L25-M25), I25/(H25-L25-M25), 0) -> 0 | H25: =IF(ISBLANK($D25), SUMIFS(H$3:H$22, $B$3:$B$22, $E25), SUMIFS(H$3:H$22, $D$3:$D$22, $D25, $B$3:$B$22, $E25)) -> 0 | I25: =IF(ISBLANK($D25), SUMIFS(I$3:I$22, $B$3:$B$22, $E25), SUMIFS(I$3:I$22, $D$3:$D$22, $D25, $B$3:$B$22, $E25)) -> 0 | J25: =IF(ISBLANK($D25), SUMIFS(J$3:J$22, $B$3:$B$22, $E25), SUMIFS(J$3:J$22, $D$3:$D$22, $D25, $B$3:$B$22, $E25)) -> 0 | K25: =IF(ISBLANK($D25), SUMIFS(K$3:K$22, $B$3:$B$22, $E25), SUMIFS(K$3:K$22, $D$3:$D$22, $D25, $B$3:$B$22, $E25)) -> 0 | L25: =IF(ISBLANK($D25), SUMIFS(L$3:L$22, $B$3:$B$22, $E25), SUMIFS(L$3:L$22, $D$3:$D$22, $D25, $B$3:$B$22, $E25)) -> 0 | M25: =IF(ISBLANK($D25), SUMIFS(M$3:M$22, $B$3:$B$22, $E25), SUMIFS(M$3:M$22, $D$3:$D$22, $D25, $B$3:$B$22, $E25)) -> 0
C26: =E26 & (IF(ISBLANK(D26), " (통합)", " (" & D26 & "차)")) -> macOS (통합) | E26: macOS | F26: =IF(H26-L26, (H26-L26-M26)/(H26-L26), 0) -> 0 | G26: =if((H26-L26-M26), I26/(H26-L26-M26), 0) -> 0 | H26: =IF(ISBLANK($D26), SUMIFS(H$3:H$22, $B$3:$B$22, $E26), SUMIFS(H$3:H$22, $D$3:$D$22, $D26, $B$3:$B$22, $E26)) -> 0 | I26: =IF(ISBLANK($D26), SUMIFS(I$3:I$22, $B$3:$B$22, $E26), SUMIFS(I$3:I$22, $D$3:$D$22, $D26, $B$3:$B$22, $E26)) -> 0 | J26: =IF(ISBLANK($D26), SUMIFS(J$3:J$22, $B$3:$B$22, $E26), SUMIFS(J$3:J$22, $D$3:$D$22, $D26, $B$3:$B$22, $E26)) -> 0 | K26: =IF(ISBLANK($D26), SUMIFS(K$3:K$22, $B$3:$B$22, $E26), SUMIFS(K$3:K$22, $D$3:$D$22, $D26, $B$3:$B$22, $E26)) -> 0 | L26: =IF(ISBLANK($D26), SUMIFS(L$3:L$22, $B$3:$B$22, $E26), SUMIFS(L$3:L$22, $D$3:$D$22, $D26, $B$3:$B$22, $E26)) -> 0 | M26: =IF(ISBLANK($D26), SUMIFS(M$3:M$22, $B$3:$B$22, $E26), SUMIFS(M$3:M$22, $D$3:$D$22, $D26, $B$3:$B$22, $E26)) -> 0
B27: 전체 | C27: 전체 통합 | D27: - | E27: - | F27: =IF(H27-L27, (H27-L27-M27)/(H27-L27), 0) -> 0 | G27: =if((H27-L27-M27), I27/(H27-L27-M27), 0) -> 0 | H27: =SUM(H3:H22) -> 7876 | I27: =SUM(I3:I22) -> 0 | J27: =SUM(J3:J22) -> 0 | K27: =SUM(K3:K22) -> 0 | L27: =SUM(L3:L22) -> 220 | M27: =SUM(M3:M22) -> 7656
B28: 시트 통계 | N28: TC리뷰
B29: No. | C29: _x001b_구분 (시트이름) | D29: Iteration | E29: 환경 | F29: Coverage | G29: Pass Rate | H29: Total | I29: P | J29: F | K29: B | L29: N/I | M29: N/R | O29: 비고 | Q29: 각 시트별 통계는 테스트 케이스 시트에 하단의 통계를 참조하여 자동 노출됩니다. 배경이 흰색인 셀은 변경 가능하며, 그외 셀은 변경하지 마세요. (시트명은 각 시트별 젤 상단 셀에만 입력하면 자동 입력됩니다.)
B30: 1 | C30: 1.가입 | D30: ='1.가입'!$H$668 -> 6 | E30: ='1.가입'!$H$669 -> a16 | F30: ='1.가입'!$H$672 -> 0 | G30: ='1.가입'!$H$673 -> 0 | H30: ='1.가입'!$H$674 -> 102 | I30: ='1.가입'!$H$675 -> 0 | J30: ='1.가입'!$H$676 -> 0 | K30: ='1.가입'!$H$677 -> 0 | L30: ='1.가입'!$H$678 -> 4 | M30: ='1.가입'!$H$679 -> 98 | N30: {=INDIRECT("'" & C30 & "'!$AG$1")} -> 0
C31: =IF(C30 = "{시트이름 입력}", "", C30) -> 1.가입 | D31: ='1.가입'!$I$668 -> 6 | E31: ='1.가입'!$I$669 -> i18 | F31: ='1.가입'!$I$672 -> 0 | G31: ='1.가입'!$I$673 -> 0 | H31: ='1.가입'!$I$674 -> 102 | I31: ='1.가입'!$I$675 -> 0 | J31: ='1.가입'!$I$676 -> 0 | K31: ='1.가입'!$I$677 -> 0 | L31: ='1.가입'!$I$678 -> 4 | M31: ='1.가입'!$I$679 -> 98
C32: =IF(C30 = "{시트이름 입력}", "", C30) -> 1.가입 | D32: ='1.가입'!$J$668 | E32: ='1.가입'!$J$669 | F32: ='1.가입'!$J$672 | G32: ='1.가입'!$J$673 | H32: ='1.가입'!$J$674 | I32: ='1.가입'!$J$675 | J32: ='1.가입'!$J$676 | K32: ='1.가입'!$J$677 | L32: ='1.가입'!$J$678 | M32: ='1.가입'!$J$679
C33: =IF(C30 = "{시트이름 입력}", "", C30) -> 1.가입 | D33: ='1.가입'!$K$668 | E33: ='1.가입'!$K$669 | F33: ='1.가입'!$K$672 | G33: ='1.가입'!$K$673 | H33: ='1.가입'!$K$674 | I33: ='1.가입'!$K$675 | J33: ='1.가입'!$K$676 | K33: ='1.가입'!$K$677 | L33: ='1.가입'!$K$678 | M33: ='1.가입'!$K$679
C34: =IF(C30 = "{시트이름 입력}", "", C30) -> 1.가입 | D34: ='1.가입'!$L$668 | E34: ='1.가입'!$L$669 | F34: ='1.가입'!$L$672 -> 0 | G34: ='1.가입'!$L$673 -> 0 | H34: ='1.가입'!$L$674 -> 296 | I34: ='1.가입'!$L$675 -> 0 | J34: ='1.가입'!$L$676 -> 0 | K34: ='1.가입'!$L$677 -> 0 | L34: ='1.가입'!$L$678 -> 0 | M34: ='1.가입'!$L$679 -> 296
C35: =IF(C30 = "{시트이름 입력}", "", C30) -> 1.가입 | D35: ='1.가입'!$M$668 | E35: ='1.가입'!$M$669 | F35: ='1.가입'!$M$672 -> 0 | G35: ='1.가입'!$M$673 -> 0 | H35: ='1.가입'!$M$674 -> 296 | I35: ='1.가입'!$M$675 -> 0 | J35: ='1.가입'!$M$676 -> 0 | K35: ='1.가입'!$M$677 -> 0 | L35: ='1.가입'!$M$678 -> 0 | M35: ='1.가입'!$M$679 -> 296
C36: =IF(C30 = "{시트이름 입력}", "", C30) -> 1.가입 | D36: ='1.가입'!$N$668 | E36: ='1.가입'!$N$669 | F36: ='1.가입'!$N$672 -> 0 | G36: ='1.가입'!$N$673 -> 0 | H36: ='1.가입'!$N$674 -> 296 | I36: ='1.가입'!$N$675 -> 0 | J36: ='1.가입'!$N$676 -> 0 | K36: ='1.가입'!$N$677 -> 0 | L36: ='1.가입'!$N$678 -> 0 | M36: ='1.가입'!$N$679 -> 296
C37: =IF(C30 = "{시트이름 입력}", "", C30) -> 1.가입 | D37: ='1.가입'!$O$668 | E37: ='1.가입'!$O$669 | F37: ='1.가입'!$O$672 -> 0 | G37: ='1.가입'!$O$673 -> 0 | H37: ='1.가입'!$O$674 -> 296 | I37: ='1.가입'!$O$675 -> 0 | J37: ='1.가입'!$O$676 -> 0 | K37: ='1.가입'!$O$677 -> 0 | L37: ='1.가입'!$O$678 -> 0 | M37: ='1.가입'!$O$679 -> 296
C38: =IF(C30 = "{시트이름 입력}", "", C30) -> 1.가입 | D38: ='1.가입'!$P$668 | E38: ='1.가입'!$P$669 | F38: ='1.가입'!$P$672 -> 0 | G38: ='1.가입'!$P$673 -> 0 | H38: ='1.가입'!$P$674 -> 296 | I38: ='1.가입'!$P$675 -> 0 | J38: ='1.가입'!$P$676 -> 0 | K38: ='1.가입'!$P$677 -> 0 | L38: ='1.가입'!$P$678 -> 0 | M38: ='1.가입'!$P$679 -> 296
C39: =IF(C30 = "{시트이름 입력}", "", C30) -> 1.가입 | D39: ='1.가입'!$Q$668 | E39: ='1.가입'!$Q$669 | F39: ='1.가입'!$Q$672 -> 0 | G39: ='1.가입'!$Q$673 -> 0 | H39: ='1.가입'!$Q$674 -> 296 | I39: ='1.가입'!$Q$675 -> 0 | J39: ='1.가입'!$Q$676 -> 0 | K39: ='1.가입'!$Q$677 -> 0 | L39: ='1.가입'!$Q$678 -> 0 | M39: ='1.가입'!$Q$679 -> 296
C40: =IF(C30 = "{시트이름 입력}", "", C30) -> 1.가입 | D40: ='1.가입'!$R$668 | E40: ='1.가입'!$R$669 | F40: ='1.가입'!$R$672 -> 0 | G40: ='1.가입'!$R$673 -> 0 | H40: ='1.가입'!$R$674 -> 296 | I40: ='1.가입'!$R$675 -> 0 | J40: ='1.가입'!$R$676 -> 0 | K40: ='1.가입'!$R$677 -> 0 | L40: ='1.가입'!$R$678 -> 0 | M40: ='1.가입'!$R$679 -> 296
...

Sheet 1.가입
G1: P(우선순위)1수행 * Regression 테스트 중 가입 이슈 발생시 moz로 어싸인 부탁드립니다. | AG1: =COUNTIF(AG5:AG686, "?*") -> 0
A2: 분류1 | B2: 분류2 | C2: 분류3 | D2: 분류4 (기능) | E2: 사전 조건 | F2: Test Step (체크할 항목) | G2: 기대결과 | H2: 6 | I2: 6 | AB2: 분류 | AE2: Comment & Jira | AF2: Spec & Tip | AG2: TC Review | AH2: Memo
H3: =IF(COUNTIF('리그레션 플랜'!C12:D12, "a15"), "a15", IF(COUNTIF('리그레션 플랜'!C12:D12, "a16"), "a16", "")) -> a16 | I3: =IF(COUNTIF('리그레션 플랜'!C12:D12, "i18"), "i18", IF(COUNTIF('리그레션 플랜'!C12:D12, "i26"), "i26", "")) -> i18 | AB3: =COUNTIF($AB5:$AB665, "<=" & MAX('입력값'!$L$3:$L686)) -> 296 | AD3: v26.4.0 | AE3: 작성 : TE | 관리 : TE/QA | AF3: 작성 : TE & QA | 관리 : QA | AG3: 작성 : TE | 관리 : QA | AH3: 작성 : anyone | 관리 : 작성자
AB4: P | AC4: C | AD4: V | AE4: 수행중 발견한 버그의 링크. 닫힘 확인한 사람이 삭제. | AF4: 스펙 및 테스트팁 | AG4: TE가 TC 수정 요청 및 문의, QA가 반영 완료 후 삭제 | AH4: 테스트 진행 중 필요한 메모 입력
A5: 가입 | H5: - | AB5: -
A6: 앱 설치 후 최초 실행 | B6: iOS Only | AB6: - | AC6: app | AD6: v25.2.0
A7: 알림 권한 허용 요청 | H7: - | I7: - | AB7: - | AC7: I | AD7: v25.2.0
B8: 알림 권한 허용 요청 팝업 표시 확인 | E8: 최초 설치 | F8: 앱 설치 후 최초 실행 | G8: 카카오톡 시작화면 내 팝업이 표시된다. ---------- '카카오톡'에서 알림을 보내고자 합니다. 경고, 사운드 및 아이콘 배지가 알림에 포함될 수 있습니다. 설정에서 이를 구성할 수 있습니다. 허용 안함 , 허용 | H8: n | AB8: 1 | AC8: I | AD8: v25.2.0
B9: 알림 권한 설정 확인 | H9: - | AB9: - | AC9: I | AD9: v25.2.0
C10: 권한 허용 안함 | F10: 팝업에서 "허용 안함" 선택 후 권한 확인 | G10: 디바이스 설정 - 알림 - 카카오톡 알림 허용 확인 시 Off로 설정 | H10: n | T10: 1 | AB10: 1 | AC10: I | AD10: v25.2.0
C11: 권한 허용 | F11: 팝업에서 "허용" 선택 후 권한 확인 | G11: 설정 - 알림 - 카카오톡 알림 허용 확인 시 On으로 설정 | H11: n | AB11: 1 | AC11: I | AD11: v25.2.0
A12: 로그인 화면(LOGIN) | AB12: - | AC12: app | AD12: v25.2.0
A13: (참고) 화면 내 컴포넌트 | F13: 문구 저장 위치 | G13: 문구 | AB13: - | AC13: app | AD13: v25.2.0
A14: 디스크립션 | F14: 클라 문구 | G14: 카카오톡을 시작합니다. | H14: - | I14: - | AB14: - | AC14: app | AD14: _x0008_v25.2.0 | AF14: (moz 25/3) Android 디스크립션, 문구 차이 존재, 추후 가입단계 flow변경 시 정리
F15: 클라 문구 | G15: (iOS Only) 사용하던 카카오계정이 있다면 이메일 또는 전화번호로 로그인해 주세요. | H15: - | I15: - | AB15: - | AC15: app | AD15: _x0008_v25.2.0 | AF15: iOS만 존재 문구 (moz) iOS/Android 통일되지 않음 - 추후개선시 체크
A16: 계정 입력 필드 | D16: 디폴트 문구 | F16: 클라 문구 | G16: 이메일 또는 전화번호 | H16: - | I16: - | AB16: - | AC16: app | AD16: _x0008_v25.2.0
A17: 비밀번호 입력 필드 | D17: 디폴트 문구 | F17: 클라 문구 | G17: 비밀번호 | H17: - | I17: - | AB17: - | AC17: app | AD17: _x0008_v25.2.0
A18: 로그인 버튼 | F18: 클라 문구 | G18: Android - 로그인 iOS - 카카오계정 로그인 | H18: - | I18: - | AB18: - | AC18: app | AD18: _x0008_v25.2.0 | AF18: 버튼 문구는 카카오계정 로그인으로 개선 필요한것으로 추정 - 가입화면 개선시 노티예정
A19: 계정생성 버튼 | F19: 클라 문구 | G19: 새로운 카카오계정 만들기 | H19: - | I19: - | AB19: - | AC19: app | AD19: _x0008_v25.2.0
A20: 비밀번호 찾기 링크 | F20: 클라 문구 | G20: 카카오계정 또는 비밀번호 찾기 | H20: - | I20: - | AB20: - | AC20: app | AD20: _x0008_v25.2.0
A21: 로그인 화면 내 기능/로직 확인
A22: 로그인 제한 | H22: - | I22: - | AB22: - | AC22: app | AD22: _x0008_v25.2.0
B23: 인증뺏긴 전화번호 계정 로그인 제한 | E23: 인증뺏김 상태 전화번호 계정 상태에서 인증뺏김 상태 | F23: 1. 로그인 화면에서 사전조건의 계정 입력 후 [카카오계정 로그인] 버튼 클릭 | G23: 1. 팝업이 표시된다. : 카카오 계정 또는 비밀번호를 다시 확인해주세요. [확인] | AB23: 3 | AC23: app | AD23: _x0008_v25.2.0
A24: 국가 코드 자동 입력 | F24: * 전화번호 계정으로 시작 시 전화번호 인증 화면에서 국가코드를 KR으로 자동 입력 * 국가코드는 디바이스 언어 설정에 영향을 받으므로, 해당 설정보다 우선체크되는지 확인한다. | H24: - | I24: - | AB24: - | AC24: app | AD24: _x0008_v25.2.0
B25: 국가코드 설정 우선순위 확인 | E25: 언어설정 : 한국 외 | F25: 1. 로그인 화면에서 010번호로 로그인 2. 약관 동의 후 전화번호 입력 화면의 국가코드 확인 | G25: 2. 국가코드는 +82 로 선택되어 표시된다. | AB25: 3 | AC25: app | AD25: _x0008_v25.2.0
A26: 전화번호 계정 노멀라이즈 | H26: - | I26: - | AB26: - | AC26: app | AD26: _x0008_v25.2.0
B27: + 문자 노멀라이즈 처리 | E27: +82NNNNNNNNNNN | F27: 1. 전화번호 계정을 사전조건의 형태로 입력 후 로그인 시도 | G27: 1. 인증번호 입력단계로 이동된다. | AB27: 3 | AC27: app | AD27: _x0008_v25.2.0
B28: -처리 | E28: NNN-NNNN-NNNN | F28: 1. 전화번호 계정을 사전조건의 형태로 입력 후 로그인 시도 | G28: 1. 인증번호 입력단계로 이동된다. | AB28: 3 | AC28: app | AD28: _x0008_v25.2.0
B29: 스페이스 처리 | E29: NNN NNNN NNNN | F29: 1. 전화번호 계정을 사전조건의 형태로 입력 후 로그인 시도 | G29: 1. 인증번호 입력단계로 이동된다. | AB29: 3 | AC29: app | AD29: _x0008_v25.2.0
A30: 비밀번호 자리수 체크로직 | F30: * 비밀자리수는 4~32자리수로 체크한다. - 신규생성은 8자리 이상만 가능 - 기존계정은 4자리 이상가능하여 4~32자리 | H30: - | I30: - | AB30: - | AC30: app | AD30: _x0008_v25.2.0
B31: 비밀번호 자리수 제한 확인 | E31: 3자 입력 | F31: 1. 비밀번호 3자까지 입력 2. 비밀번호 4자까지 입력 3. 비밀번호 32자까지 입력 4. 비밀번호 32자 초과 입력 | G31: 1. [카카오계정 로그인] 버튼 비활성화 2. [카카오계정 로그인] 버튼 활성화된다. 3. 32자 비밀번호가 입력된다. 4. 32자 초과 자리수는 입력되지 않는다. | AB31: 1 | AC31: app | AD31: _x0008_v25.2.0 | AF31: Android [로그인] 노출 추후 가입화면 개선시 노티예정
E32: 4자 | F32: 1. 비밀번호 4자인 계정 입력 후 로그인 시도 | G32: 1. 로그인 시도가 처리되며, 약관 동의 화면으로 전환 | AB32: 3 | AC32: app | AD32: _x0008_v25.2.0
E33: 32자 | F33: 1. 비밀번호 32자인 계정 입력 후 로그인 시도 | G33: 1. 로그인 시도가 처리되며, 약관 동의 화면으로 전환 | AB33: 3 | AC33: app | AD33: _x0008_v25.2.0
A34: 계정 유효성 확인 | F34: * ID/PW 입력 상태 별 오류 팝업 확인 | H34: - | I34: - | AB34: - | AC34: app | AD34: _x0008_v25.2.0
B35: 모두 유효 | F35: * 모두 유효한 경우에는 팝업 미 발생 - 테스트 스킵 | H35: - | I35: - | AB35: - | AC35: app | AD35: _x0008_v25.2.0
B36: ID오입력 | E36: 존재하지 않는 계정 | F36: 1. 이메일 또는 전화번호 필드에 존재하지 않는 계정 입력 후 [카카오계정 로그인] 버튼 클릭 2. [확인] 버튼 클릭 | G36: 1. 팝업이 발생된다. : 카카오계정 또는 비밀번호를 다시 확인해 주세요.[확인] 2. 팝업이 닫힌다. | AB36: 1 | AC36: app | AD36: _x0008_v25.2.0
B37: PW오입력 | F37: 1. 잘못된 비밀번호 입력 후 로그인 시도 2. [확인] 버튼 클릭 | G37: 1. 팝업이 발생된다. : 카카오계정 또는 비밀번호를 다시 확인해 주세요.[확인] 2. 팝업이 닫힌다. | AB37: 1 | AC37: app | AD37: _x0008_v25.2.0
A38: 비밀번호 입력 제한 | F38: * 비밀번호 입력은 2시간이전~현재시간 내에 총 카운트로 제한하며 20회로 제한한다. * 현재 카운트 및 초기화는 계정 어드민 사용 : https://admin-account.kakao.com/tools/reset_counts/search | H38: - | I38: - | AB38: - | AC38: app | AD38: _x0008_v25.2.0
B39: 입력제한 확인 | E39: 오입력 19회 상태 | F39: 1. 비밀번호 오입력 상태로 로그인 시도(19회상태) 2. 비밀번호 오입력 상태로 로그인 시도(20회상태) | G39: 1. 팝업이 발생된다. : 카카오계정 또는 비밀번호를 다시 확인해 주세요.[확인] 2. 팝업이 발생된다. : 비밀번호 입력 제한 횟수를 초과했습니다. 2시간 후에 다시 시도해 주세요. (확인) | AB39: 3 | AC39: app | AD39: _x0008_v25.2.0
F40: 1. 비밀번호 오입력 후 팝업을 닫는다. | G40: 1. [확인] 버튼이 비활성화로 변경 | AB40: 3 | AC40: app | AD40: _x0008_v25.2.0
...

Sheet 2.친구
A1: 담당자: joy.2 | AB1: 수행 범위: P1 ~ P3 | AG1: =COUNTIF(AG5:AG210, "?*") -> 4
A2: 분류1 | B2: 분류2 | C2: 분류3 | D2: 분류4 (기능) | E2: 사전 조건 | F2: Test Step (체크할 항목) | G2: 기대결과 | H2: 6 | I2: 6 | AB2: 분류 | AE2: Comment & Jira | AF2: Spec & Tip | AG2: TC Review | AH2: Memo
H3: =IF(COUNTIF('리그레션 플랜'!C12:D12, "a15"), "a15", IF(COUNTIF('리그레션 플랜'!C12:D12, "a16"), "a16", "")) -> a16 | I3: =IF(COUNTIF('리그레션 플랜'!C12:D12, "i18"), "i18", IF(COUNTIF('리그레션 플랜'!C12:D12, "i26"), "i26", "")) -> i18 | AB3: =COUNTIF($AB5:$AB187, "<=" & MAX('입력값'!$L$3:$L210)) -> 112 | AD3: v26.6.0 | AE3: 작성 : TE | 관리 : TE/QA | AF3: 작성 : TE & QA | 관리 : QA | AG3: 작성 : TE | 관리 : QA | AH3: 작성 : anyone | 관리 : 작성자
AB4: P | AC4: C | AD4: V | AE4: 수행중 발견한 버그의 링크. 닫힘 확인한 사람이 삭제. | AF4: 스펙 및 테스트팁 | AG4: TE가 TC 수정 요청 및 문의, QA가 반영 완료 후 삭제 | AH4: 테스트 진행 중 필요한 메모 입력
A5: GNB | F5: ** (joy) 테스트 진행 전 숏폼 크리에이터 친추 많이 해두고 시작 부탁드리겠습니다 (26/6 숏폼 크리에이터 게시물 스펙 추가로 인해 친구 추가 많이해두고 추천 서버 거쳐 4시간 뒤쯤부터 소식칩에 노출) | H5: - | I5: - | AB5: - | AC5: - | AD5: -
A6: 내프로필 | F6: 1. 내프로필 영역 UI 확인 2. 내프로필 영역 탭 | G6: 1. 친구탭에 표시된 내프로필 확인 - 이름 표시 ㄴ 최대 표시 글자수: 7자 ㄴ 최대 표시 글자수 초과시 : 공간에 맞는 글자수 표시 + 말줄임 (말줄임 이전에 표시되는 글자수는 가변적) 2. 내프로필이 조회됨 | AB6: 1 | AC6: app | AD6: v25.10.0
A7: 친구칩 > 친구추가 | H7: - | I7: - | AB7: - | AC7: app | AD7: v25.8.0
B8: QR코드 | F8: 친구칩 > 친구추가> [QR코드]를 통해 친구 추가 | G8: QR코드 스캔을 통해 친구가 추가됨 * 진입시 카메라 권한, 앨범 진입시 사진 접근 권한 필요 * 자신의 QR코드 read시 안내 팝업 표시 | AB8: 1 | AC8: app | AD8: v25.8.0
B9: 연락처 | F9: 친구칩 > 친구추가> [연락처]를 통해 친구 추가 | G9: 연락처로 친구가 추가됨 *이미 친구인 유저 검색시 안내 문구 및 채팅 유도 버튼 표시 ㄴ 내 연락처인 경우 [나와의 채팅] 버튼 표시 *[휴대폰 연락처에 추가] label 버튼을 통해 기기 저장 가능 | AB9: 1 | AC9: app | AD9: v25.8.0
B10: 카카오톡 ID | F10: 친구칩 > 친구추가> [카카오톡 ID]를 통해 친구 추가 | G10: 검색한 ID에 해당하는 유저가 친구로 추가됨 *대상자가 검색 비허용 or 없는 ID인 경우 "검색 결과 없음" 표시 *내 ID 검색시 [나와의 채팅] 버튼 표시 | AB10: 1 | AC10: app | AD10: v25.8.0
B11: 추천친구 | H11: - | I11: - | AB11: - | AC11: app | AD11: v25.8.0
C12: 추천 친구 없음 | F12: 친구탭> 친구추가> [추천친구] 진입시 추천 친구가 없을 때 목록 UI 확인 | G12: [뒤로(<)] 추천친구 채널(AD) [채널 카드1] [채널 카드2] ... "추천친구가 없어요." *채널을 추가해도 목록은 갱신되지 않고 버튼 레이블만 변경됨 | AB12: 4 | AC12: app | AD12: v25.8.0
C13: 추천 친구 삭제 | F13: 0. [추천친구] 진입 1. 추천친구 슬롯 롱탭(or 스와이프) 2. context menu에서 [삭제] 선택 3. 삭제 확인 얼럿 [삭제] 선택 | G13: 1. context menu가 표시됨 [삭제] 2. 추천친구 삭제 확인 얼럿 표시됨 3. - 추천친구가 삭제됨 - 타임라인에 표시됐던 추천친구의 게시물 및 상태메시지가 있는 경우 즉시 제거됨 | AB13: 3 | AC13: app | AD13: v26.2.0 | AF13: (trudy,25/11) 신규 가입한 유저 > 추천친구 채널AD 미노출 현상 https://jira.daumkakao.com/browse/QATEAM-8959 ㄴ 타부서 이슈로 Close 처리
C14: 목록에서 추가 | F14: 추천친구 목록에서 [친구 추가] 버튼 탭 | G14: - [친구 추가] 버튼 > [채팅] 버튼으로 변경 - 재진입시 추천 친구 목록에서 사라짐 - 친구탭> [친구 n >] 레이블 버튼에 빨간점이 표시되고 친구목록> 새로운 친구 n 섹션에 추가됨 (w/빨간점) *친구목록> 친구n 섹션에는 빨간점 표시 없음 | AB14: 2 | AC14: app | AD14: v25.8.0 | AF14: (mia, 26/5) - android : 친구 추가 후 최하단으로 위치 변경됨
